Workbook
Name ACTION: #REF!
Name ACTION: #REF!

Sheet Cover
B2: TEST REPORT DOCUMENT
A4: Project Name | B4: Online Learning Platform – SkillUp | E4: Creator | F4: TuanCM
A5: Project Code | B5: OLP-SkillUp | E5: Issue Date | F5: 45978
A6: Document Code | B6: =B5&"_"&"Integration_Test_Report"&"" -> OLP-SkillUp_Integration_Test_Report | E6: Version | F6: 1.0
A9: Record of change
A10: Effective Date | B10: Version | C10: Change Item | D10: *A,D,M | E10: Change description | F10: Reference
A11: 45978 | B11: 1.0 | D11: A | E11: Initialize Integration Test
A12: 45978 | B12: 1.0 | C12: Test Cases, Test Statistics | D12: A | E12: Implement test cases for Iteration 1.
A13: 45978 | B13: 1.0 | C13: Test Cases, Test Statistics | D13: M | E13: Implement test cases for Iteration 2.
A14: 45978 | B14: 1.0 | C14: Test Cases, Test Statistics | D14: M | E14: Implement test cases for Iteration 3.

Sheet Test Cases
D1: TEST CASE LIST
B3: Project Name | D3: Online Learning Platform – SkillUp
B4: Project Code | D4: OLP-SkillUp
B5: Test Environment Setup Description | D5: 1. Server 2. SQLServer 3.Google Chrome, Microsoft Edge 4. Microsoft Visual Studio
B8: No | C8: Function Name | D8: Sheet Name | E8: Description | F8: Pre-Condition
B9: 1 | C9: =Register!B2 -> Register | D9: Register
B10: 2 | C10: Login by account | D10: Login by account
B11: 3 | C11: Login by google | D11: Login by google
B12: 4 | C12: Forgot password | D12: Forgot password
B13: 5 | C13: Logout | D13: Logout
B14: 6 | C14: View profile | D14: View profile
B15: 7 | C15: Update profile | D15: Update profile
B16: 8 | C16: Change password | D16: Change password
B17: 9 | C17: View purchase history | D17: View purchase history
B18: 10 | C18: View cart | D18: View cart
B19: 11 | C19: Add to cart | D19: Add to cart
B20: 12 | C20: Remove from cart | D20: Remove from cart
B21: 13 | C21: Add course | D21: Add course
... B42: 34 | C42: Email notification | D42: Email notification

Sheet Test Statistics
B1: TEST STATISTICS
B3: Project Name | C3: Online Learning Platform – SkillUp | E3: Creator | H3: TuanCM
B4: Project Code | C4: OLP-SkillUp | E4: Reviewer/Approver
B5: Document Code | C5: =C4&"_"&"System_Test_Report"&"" -> OLP-SkillUp_System_Test_Report | E5: Issue Date | H5: 45964
B6: Notes
B10: No | C10: Module code | D10: Passed | E10: Failed | F10: Pending | G10: N/A | H10: Number of test cases
B11: 1 | C11: Register | D11: =Register!B6 -> 3 | E11: =Register!C6 -> 0 | F11: =Register!D6 -> 0 | G11: =Register!E6 -> 0 | H11: =Register!B4 -> 3
B12: 2 | C12: Login by account | D12: ='Login by account'!B6 -> 3 | E12: ='Login by account'!C6 -> 0 | F12: ='Login by account'!D6 -> 0 | G12: ='Login by account'!E6 -> 0 | H12: ='Login by account'!B4 -> 3
B13: 3 | C13: Login by google | D13: ='Login by Google'!B6 -> 1 | E13: ='Login by Google'!C6 -> 0 | F13: ='Login by Google'!D6 -> 0 | G13: ='Login by Google'!E6 -> 0 | H13: ='Login by Google'!B4 -> 1
B14: 4 | C14: Forgot password | D14: ='Forgot password'!B6 -> 2 | E14: ='Forgot password'!C6 -> 0 | F14: ='Forgot password'!D6 -> 0 | G14: ='Forgot password'!E6 -> 0 | H14: ='Forgot password'!B4 -> 2
B15: 5 | C15: Logout | D15: =Logout!B6 -> 3 | E15: =Logout!C6 -> 0 | F15: =Logout!D6 -> 0 | G15: =Logout!E6 -> 0 | H15: =Logout!B4 -> 3
B16: 6 | C16: View profile | D16: ='View user profile'!B6 -> 1 | E16: ='View user profile'!C6 -> 0 | F16: ='View user profile'!D6 -> 0 | G16: ='View user profile'!E6 -> 0 | H16: ='View user profile'!B4 -> 1
B17: 7 | C17: Update profile | D17: ='Update user profile'!B6 -> 2 | E17: ='Update user profile'!C6 -> 0 | F17: ='Update user profile'!D6 -> 0 | G17: ='Update user profile'!E6 -> 0 | H17: ='Update user profile'!B4 -> 2
B18: 8 | C18: Change password | D18: ='Change password'!B6 -> 4 | E18: ='Change password'!C6 -> 0 | F18: ='Change password'!D6 -> 0 | G18: ='Change password'!E6 -> 0 | H18: ='Change password'!B4 -> 4
B19: 9 | C19: View purchase history | D19: ='View purchase history'!B6 -> 2 | E19: ='View purchase history'!C6 -> 0 | F19: ='View purchase history'!D6 -> 0 | G19: ='View purchase history'!E6 -> 0 | H19: ='View purchase history'!B4 -> 2
B20: 10 | C20: View cart | D20: ='View cart'!B6 -> 2 | E20: ='View cart'!C6 -> 0 | F20: ='View cart'!D6 -> 0 | G20: ='View cart'!E6 -> 0 | H20: ='View cart'!B4 -> 2
B21: 11 | C21: Add to cart | D21: ='Add to cart'!B6 -> 3 | E21: ='Add to cart'!C6 -> 0 | F21: ='Add to cart'!D6 -> 0 | G21: ='Add to cart'!E6 -> 0 | H21: ='Add to cart'!B4 -> 3
B22: 12 | C22: Remove from cart | D22: ='Remove item from cart'!B6 -> 2 | E22: ='Remove item from cart'!C6 -> 0 | F22: ='Remove item from cart'!D6 -> 0 | G22: ='Remove item from cart'!E6 -> 0 | H22: ='Remove item from cart'!B4 -> 2
B23: 13 | C23: Add course | D23: ='Add course'!B6 -> 2 | E23: ='Add course'!C6 -> 0 | F23: ='Add course'!D6 -> 0 | G23: ='Add course'!E6 -> 0 | H23: ='Add course'!B4 -> 2
B24: 14 | C24: Hide course | D24: ='Hide course'!B6 -> 1 | E24: ='Hide course'!C6 -> 0 | F24: ='Hide course'!D6 -> 0 | G24: ='Hide course'!E6 -> 0 | H24: ='Hide course'!B4 -> 1
B25: 15 | C25: Update course - general | D25: ='Update course - general'!B6 -> 9 | E25: ='Update course - general'!C6 -> 0 | F25: ='Update course - general'!D6 -> 0 | G25: ='Update course - general'!E6 -> 0 | H25: ='Update course - general'!B4 -> 9
B26: 16 | C26: View section | D26: ='View sections'!B6 -> 2 | E26: ='View sections'!C6 -> 0 | F26: ='View sections'!D6 -> 0 | G26: ='View sections'!E6 -> 0 | H26: ='View sections'!B4 -> 2
B27: 17 | C27: Add section | D27: ='Add sections'!B6 -> 4 | E27: ='Add sections'!C6 -> 0 | F27: ='Add sections'!D6 -> 0 | G27: ='Add sections'!E6 -> 0 | H27: ='Add sections'!B4 -> 4
B28: 18 | C28: Edit section | D28: ='Update sections'!B6 -> 3 | E28: ='Update sections'!C6 -> 0 | F28: ='Update sections'!D6 -> 0 | G28: ='Update sections'!E6 -> 0 | H28: ='Update sections'!B4 -> 3
B29: 19 | C29: Delete section | D29: ='Delete sections'!B6 -> 1 | E29: ='Delete sections'!C6 -> 0 | F29: ='Delete sections'!C6 -> 0 | G29: ='Delete sections'!E6 -> 0 | H29: ='Delete sections'!B4 -> 1
B30: 20 | C30: Create lesson | D30: ='Create lesson'!B6 -> 6 | E30: ='Create lesson'!C6 -> 0 | F30: ='Create lesson'!D6 -> 0 | G30: ='Create lesson'!E6 -> 0 | H30: ='Create lesson'!B4 -> 6
B31: 21 | C31: Create question | D31: ='Create question'!B6 -> 4 | E31: ='Create question'!C6 -> 0 | F31: ='Create question'!D6 -> 0 | G31: ='Create question'!E6 -> 0 | H31: ='Create question'!B4 -> 4
B32: 22 | C32: Add from bank | D32: ='Add question from bank'!B6 -> 2 | E32: ='Add question from bank'!C6 -> 0 | F32: ='Add question from bank'!D6 -> 0 | G32: ='Add question from bank'!E6 -> 0 | H32: ='Add question from bank'!B4 -> 2
B33: 23 | C33: View question | D33: ='View question'!B6 -> 2 | E33: ='View question'!C6 -> 0 | F33: ='View question'!D6 -> 0 | G33: ='View question'!E6 -> 0 | H33: ='View question'!B4 -> 2
B34: 24 | C34: Edit question | D34: ='Edit question'!B6 -> 3 | E34: ='Edit question'!C6 -> 0 | F34: ='Edit question'!D6 -> 0 | G34: ='Edit question'!E6 -> 0 | H34: ='Edit question'!B4 -> 3
B35: 25 | C35: Delete question | D35: ='Delete question'!B6 -> 2 | E35: ='Delete question'!C6 -> 0 | F35: ='Delete question'!D6 -> 0 | G35: ='Delete question'!E6 -> 0 | H35: ='Delete question'!B4 -> 2
B36: 26 | C36: Enroll course | D36: ='Enroll course'!B6 -> 3 | E36: ='Enroll course'!C6 -> 0 | F36: ='Enroll course'!D6 -> 0 | G36: ='Enroll course'!E6 -> 0 | H36: ='Enroll course'!B4 -> 3
B37: 27 | C37: Learning course | D37: ='Learning course'!B6 -> 3 | E37: ='Learning course'!C6 -> 0 | F37: ='Learning course'!D6 -> 0 | G37: ='Learning course'!E6 -> 0 | H37: ='Learning course'!B4 -> 3
B38: 28 | C38: Progress tracking | D38: ='Progress tracking'!B6 -> 1 | E38: ='Progress tracking'!C6 -> 0 | F38: ='Progress tracking'!D6 -> 0 | G38: ='Progress tracking'!E6 -> 0 | H38: ='Progress tracking'!B4 -> 1
B39: 29 | C39: Checkout | D39: ='Apply voucher'!B6 -> 5 | E39: ='Apply voucher'!C6 -> 0 | F39: ='Apply voucher'!D6 -> 0 | G39: ='Apply voucher'!E6 -> 0 | H39: ='Apply voucher'!B4 -> 5
B40: 30 | C40: Apply voucher | D40: =Checkout!B6 -> 5 | E40: ='Apply voucher'!C7 -> 0 | F40: ='Apply voucher'!D7 -> 0 | G40: ='Apply voucher'!E7 -> 0 | H40: ='Apply voucher'!B4 -> 5
B41: 31 | C41: Take quiz | D41: ='Take quiz'!B6 -> 6 | E41: ='Take quiz'!C6 -> 0 | F41: ='Take quiz'!D6 -> 0 | G41: ='Take quiz'!E6 -> 0 | H41: ='Take quiz'!B4 -> 6
B42: 32 | C42: View result | D42: ='View result'!B6 -> 6 | E42: ='View result'!C6 -> 0 | F42: ='View result'!D6 -> 0 | G42: ='View result'!E6 -> 0 | H42: ='View result'!B4 -> 6
B43: 33 | C43: Rating | D43: =Rating!B6 -> 2 | E43: =Rating!C6 -> 0 | F43: =Rating!D6 -> 0 | G43: =Rating!E6 -> 0 | H43: =Rating!B4 -> 2
B44: 34 | C44: Email notification | D44: ='Email notification'!B6 -> 4 | E44: ='Email notification'!C6 -> 0 | F44: ='Email notification'!D6 -> 0 | G44: ='Email notification'!E6 -> 0 | H44: ='Email notification'!B4 -> 4
...

Sheet Register
A2: Feature | B2: Register | R2: Passed
A3: Test requirement | B3: <Brief description about requirements which are tested in this sheet> | R3: Failed
A4: Number of TCs | B4: =COUNTA(A12:A867) -> 3 | R4: Pending
A5: Testing Round | B5: Passed | C5: Failed | D5: Pending | E5: N/A | R5: N/A
A6: Round 1 | B6: =COUNTIF($F10:$F865,B5) -> 3 | C6: =COUNTIF($F10:$F865,C5) -> 0 | D6: =COUNTIF($F10:$F865,D5) -> 0 | E6: =COUNTIF($F10:$F865,E5) -> 0
A7: Round 2 | B7: =COUNTIF($F10:$F865,B5) -> 3 | C7: =COUNTIF($F10:$F865,C5) -> 0 | D7: =COUNTIF($F10:$F865,D5) -> 0 | E7: =COUNTIF($F10:$F865,E5) -> 0
A8: Round 3 | B8: =COUNTIF($F10:$F865,B5) -> 3 | C8: =COUNTIF($F10:$F865,C5) -> 0 | D8: =COUNTIF($F10:$F865,D5) -> 0 | E8: =COUNTIF($F10:$F865,E5) -> 0
A10: Test Case ID | B10: Test Case Description | C10: Test Case Procedure | D10: Expected Results | E10: Pre-conditions | F10: Round 1 | G10: Test date | H10: Tester | I10: Round 2 | J10: Test date | K10: Tester | L10: Round 3 | M10: Test date | N10: Tester | O10: Note
A11: Register
A12: [Register - 1] | B12: Test registration with valid input : - Email - Password - Confirm Password - Full name | C12: 1. Enter "http://localhost:5173/" to navigate to the website. (Top-right corner of the screen) 2. Guest user click the “Đăng ký” button. 3. The site displays the registration form. 4. Guest user select a registration role: “Student” or “Lecturer.” 5. Enter the following valid information: - Email: student@gmail.com - Password: Student@123 - RePassword: Student@123 - Full Name: Nguyen Van A 6. Guest user click the “Đăng ký” button. 7. Guest user ou are redirected to the “Đăng nhập” screen. | D12: - The guest user successfully registered, is redirected to the login page and the user details are stored in the database. - Notification display system "Đăng ký thành công! Vui lòng kiểm tra email để xác thực tài khoản." - The system sends authentication to the registered user's email. | E12: Server must be work Guest user is not logged in and wants to create an account. | F12: Passed | G12: 45978 | H12: TuanCM | I12: Passed | J12: 45980 | K12: TuanCM | L12: Passed | M12: 45981 | N12: TuanCM
A13: [Register - 2] | B13: Test registration with invalid input : - Email - Password - Confirm Password - Full name | C13: 1. Enter "http://localhost:5173/" to navigate to the website. (Top-right corner of the screen) 2. Guest user clicks the “Đăng ký” button. 3. The site displays the registration form. 4. Guest user selects a registration role: “Student” or “Lecturer.” 5.Guest user enter invalid email form(e.g., quatbt.com) 6. Guest user clicks the “Đăng ký” button. 7. Website displays an error message for invaild email format 8. Guest user corrects the mail format and resubmits the form. | D13: System displays an error message for the empty fields and prevents registration until corrected. | E13: Server must be work Guest user is not logged in and wants to create an account. | F13: Passed | G13: 45978 | H13: TuanCM | I13: Passed | J13: 45980 | K13: TuanCM | L13: Passed | M13: 45981 | N13: TuanCM
A14: [Register - 3] | B14: Test registration with empty required fields: - Email - Password - Confirm Password - Full name | C14: 1. Enter "http://localhost:5173/" to navigate to the website. (Top-right corner of the screen) 2. Guest user click the “Đăng ký” button. 3. The site displays the registration form. 4. Guest user select a registration role: “Student” or “Lecturer.” 5. Enter the following valid information: - Email: empty - Password: empty - RePassword: empty - Full Name: empty 6. The registration form displays the message "vui lòng điền vào trường này". 7. The guest user corrects the inputs so no field is left blank and the format is valid, then submits the form. | D14: System displays an error message for the empty fields and prevents registration until corrected. | E14: Server must be work Guest user is not logged in and wants to create an account. | F14: Passed | G14: 45978 | H14: TuanCM | I14: Passed | J14: 45980 | K14: TuanCM | L14: Passed | M14: 45981 | N14: TuanCM

Sheet Login by account
A2: Feature | B2: Login by account | R2: Passed
A3: Test requirement | B3: <Brief description about requirements which are tested in this sheet> | R3: Failed
A4: Number of TCs | B4: =COUNTA(A12:A867) -> 3 | R4: Pending
A5: Testing Round | B5: Passed | C5: Failed | D5: Pending | E5: N/A | R5: N/A
A6: Round 1 | B6: =COUNTIF($F10:$F865,B5) -> 3 | C6: =COUNTIF($F10:$F865,C5) -> 0 | D6: =COUNTIF($F10:$F865,D5) -> 0 | E6: =COUNTIF($F10:$F865,E5) -> 0
A7: Round 2 | B7: =COUNTIF($F10:$F865,B5) -> 3 | C7: =COUNTIF($F10:$F865,C5) -> 0 | D7: =COUNTIF($F10:$F865,D5) -> 0 | E7: =COUNTIF($F10:$F865,E5) -> 0
A8: Round 3 | B8: =COUNTIF($F10:$F865,B5) -> 3 | C8: =COUNTIF($F10:$F865,C5) -> 0 | D8: =COUNTIF($F10:$F865,D5) -> 0 | E8: =COUNTIF($F10:$F865,E5) -> 0
A10: Test Case ID | B10: Test Case Description | C10: Test Case Procedure | D10: Expected Results | E10: Pre-conditions | F10: Round 1 | G10: Test date | H10: Tester | I10: Round 2 | J10: Test date | K10: Tester | L10: Round 3 | M10: Test date | N10: Tester | O10: Note
A11: Login by account
A12: [Login by account - 1] | B12: Check if the user can successfully log in with a valid email and password. | C12: 1. Enter "http://localhost:5173/" to go to website 2. Location in the right corner of the screen: - Click on "Đăng nhập" button 3. Fill in information including: - Email: user@example.com - Password: String 4. Click "Đăng nhập" button | D12: System displays message "Đăng nhập thành công!" | E12: Server must be work Guest user is not logged in and wants to create an account. | F12: Passed | G12: 45978 | H12: TuanCM | I12: Passed | J12: 45980 | K12: TuanCM | L12: Passed | M12: 45981 | N12: TuanCM
A13: [Login by account - 2] | B13: Check if the website handles an incorrect password. | C13: 1. Enter "http://localhost:5173/" to go to website 2. Location in the right corner of the screen: - Click on "Đăng nhập" button 3. Fill in information including: - Email: user@example.com - Password: String1111 4. Click "Đăng nhập" button | D13: System displays message "Email hoặc mật khẩu không đúng" | E13: Server must be work Guest user is not logged in and wants to create an account. | F13: Passed | G13: 45978 | H13: TuanCM | I13: Passed | J13: 45980 | K13: TuanCM | L13: Passed | M13: 45981 | N13: TuanCM
A14: [Login by account - 3] | B14: Check if the website handles an unregistered email address. | C14: 1. Enter "http://localhost:5173/" to go to website 2. Location in the right corner of the screen: - Click on "Đăng nhập" button 3. Fill in information including: - Email: user11@example.com - Password: String 4. Click "Đăng nhập" button | D14: System displays message "Email hoặc mật khẩu không đúng" | E14: Server must be work Guest user is not logged in and wants to create an account. | F14: Passed | G14: 45978 | H14: TuanCM | I14: Passed | J14: 45980 | K14: TuanCM | L14: Passed | M14: 45981 | N14: TuanCM

Sheet Login by Google
A2: Feature | B2: Login by Google | R2: Passed
A3: Test requirement | B3: <Brief description about requirements which are tested in this sheet> | R3: Failed
A4: Number of TCs | B4: =COUNTA(A12:A993) -> 1 | R4: Pending
A5: Testing Round | B5: Passed | C5: Failed | D5: Pending | E5: N/A | R5: N/A
A6: Round 1 | B6: =COUNTIF($F10:$F991,B5) -> 1 | C6: =COUNTIF($F10:$F991,C5) -> 0 | D6: =COUNTIF($F10:$F991,D5) -> 0 | E6: =COUNTIF($F10:$F991,E5) -> 0
A7: Round 2 | B7: =COUNTIF($F10:$F991,B5) -> 1 | C7: =COUNTIF($F10:$F991,C5) -> 0 | D7: =COUNTIF($F10:$F991,D5) -> 0 | E7: =COUNTIF($F10:$F991,E5) -> 0
A8: Round 3 | B8: =COUNTIF($F10:$F991,B5) -> 1 | C8: =COUNTIF($F10:$F991,C5) -> 0 | D8: =COUNTIF($F10:$F991,D5) -> 0 | E8: =COUNTIF($F10:$F991,E5) -> 0
A10: Test Case ID | B10: Test Case Description | C10: Test Case Procedure | D10: Expected Results | E10: Pre-conditions | F10: Round 1 | G10: Test date | H10: Tester | I10: Round 2 | J10: Test date | K10: Tester | L10: Round 3 | M10: Test date | N10: Tester | O10: Note
A11: Login by google
A12: [Login by Google- 1] | B12: Check if the user can successfully log in using a valid Google account. | C12: 1. Enter "http://localhost:5173/" to navigate to the website. (Top-right corner of the screen) 2. Guest user click the “Đăng nhập” button. 3. Click on the "Tiếp tục sử dụng dịch vụ bằng google" button. 4. The system redirects to Google’s login page. 5. The system redirects back to the application, showing the user's dashboard or homepage". | D12: System displays message "Đăng nhập Google thành công" | E12: 1.Server must be work 2..Account must be in system | F12: Passed | G12: 45978 | H12: TuanCM | I12: Passed | J12: 45980 | K12: TuanCM | L12: Passed | M12: 45981 | N12: TuanCM

Sheet Forgot password
A2: Feature | B2: Forgot password | R2: Passed
A3: Test requirement | B3: <Brief description about requirements which are tested in this sheet> | R3: Failed
A4: Number of TCs | B4: =COUNTA(A12:A866) -> 2 | R4: Pending
A5: Testing Round | B5: Passed | C5: Failed | D5: Pending | E5: N/A | R5: N/A
A6: Round 1 | B6: =COUNTIF($F10:$F864,B5) -> 2 | C6: =COUNTIF($F10:$F864,C5) -> 0 | D6: =COUNTIF($F10:$F864,D5) -> 0 | E6: =COUNTIF($F10:$F864,E5) -> 0
A7: Round 2 | B7: =COUNTIF($F10:$F864,B5) -> 2 | C7: =COUNTIF($F10:$F864,C5) -> 0 | D7: =COUNTIF($F10:$F864,D5) -> 0 | E7: =COUNTIF($F10:$F864,E5) -> 0
A8: Round 3 | B8: =COUNTIF($F10:$F864,B5) -> 2 | C8: =COUNTIF($F10:$F864,C5) -> 0 | D8: =COUNTIF($F10:$F864,D5) -> 0 | E8: =COUNTIF($F10:$F864,E5) -> 0
A10: Test Case ID | B10: Test Case Description | C10: Test Case Procedure | D10: Expected Results | E10: Pre-conditions | F10: Round 1 | G10: Test date | H10: Tester | I10: Round 2 | J10: Test date | K10: Tester | L10: Round 3 | M10: Test date | N10: Tester | O10: Note
A11: Forgot password
A12: [Forgot password- 1] | B12: Verify if the user can request a password reset by entering a valid registered email address. | C12: 1. Enter "http://localhost:5173/" to navigate to the website. (Top-right corner of the screen) 2. Guest user click the “Đăng nhập” button. 3. Guest user clicks on link "Quên mật khẩu?". 4. The system displays a form asking the user to enter their registered email address. 5. The user enters their email address and clicks the "Gửi email khôi phục" button. 6. The system sends a password reset email with a reset link to the user’s registered email address. 7. Redirect to "Đặt lại mật khẩu" screen 6. User enter the following valid information: - Mật khẩu mới: Student@123 - Xác nhận mật khẩu mới: Student@123 7. Click on "Đặt lại mật khẩu" button | D12: System displays message "Đặt lại mật khẩu thành công" | E12: 1.Server must be work 2..Account must be in system | F12: Passed | G12: 45978 | H12: TuanCM | I12: Passed | J12: 45980 | K12: TuanCM | L12: Passed | M12: 45981 | N12: TuanCM
A13: [Forgot password- 2] | B13: Enter non-existent email | C13: 1. Enter "http://localhost:5173/" to navigate to the website. (Top-right corner of the screen) 2. Guest user click the “Đăng nhập” button. 3. Guest user clicks on link "Quên mật khẩu?". 4. The system displays a form asking the user to enter their registered email address. 5. User enters an email that is not registered in the system (e.g., nanhnanh07@gmail.com). 6. Clicks the "Gửi email khôi phục" button. | D13: System displays message "Email không tồn tại hoặc chưa xác thực" | E13: 1.Server must be work 2..Account must be in system | F13: Passed | G13: 45978 | H13: TuanCM | I13: Passed | J13: 45980 | K13: TuanCM | L13: Passed | M13: 45981 | N13: TuanCM

Sheet Logout
A2: Feature | B2: Logout | R2: Passed
A3: Test requirement | B3: <Brief description about requirements which are tested in this sheet> | R3: Failed
A4: Number of TCs | B4: =COUNTA(A12:A995) -> 3 | R4: Pending
A5: Testing Round | B5: Passed | C5: Failed | D5: Pending | E5: N/A | R5: N/A
A6: Round 1 | B6: =COUNTIF($F10:$F993,B5) -> 3 | C6: =COUNTIF($F10:$F993,C5) -> 0 | D6: =COUNTIF($F10:$F993,D5) -> 0 | E6: =COUNTIF($F10:$F993,E5) -> 0
A7: Round 2 | B7: =COUNTIF($F10:$F993,B5) -> 3 | C7: =COUNTIF($F10:$F993,C5) -> 0 | D7: =COUNTIF($F10:$F993,D5) -> 0 | E7: =COUNTIF($F10:$F993,E5) -> 0
A8: Round 3 | B8: =COUNTIF($F10:$F993,B5) -> 3 | C8: =COUNTIF($F10:$F993,C5) -> 0 | D8: =COUNTIF($F10:$F993,D5) -> 0 | E8: =COUNTIF($F10:$F993,E5) -> 0
A10: Test Case ID | B10: Test Case Description | C10: Test Case Procedure | D10: Expected Results | E10: Pre-conditions | F10: Round 1 | G10: Test date | H10: Tester | I10: Round 2 | J10: Test date | K10: Tester | L10: Round 3 | M10: Test date | N10: Tester | O10: Note
A11: Logout
A12: [Logout- 1] | B12: Check if the user can successfully log out from the website. | C12: 1. Enter "http://localhost:5173/" to go to website 2. Guest user login with system. 3.Click the avatar icon in top-right of website. 4. Click "Đăng xuất" button. | D12: - User is logged out and redirect home page. No user-specific data is accessible until the user logs in again. - Show message "Đăng xuất thành công!" | E12: 1.Server must be work 2..Account must be in system | F12: Passed | G12: 45978 | H12: TuanCM | I12: Passed | J12: 45980 | K12: TuanCM | L12: Passed | M12: 45981 | N12: TuanCM
A13: [Logout- 2] | B13: Check if a logged-out user is restricted from accessing pages meant for logged-in users. | C13: 1. Enter "http://localhost:5173/" to go to website 2. Guest user login with system. 3.Click the avatar icon in top-right of website. 4. Click "Đăng xuất" button. 5. After logging out, try to directly access the restricted page by entering the URL in the browser. | D13: The system redirects the user to the homepage when they try to access the restricted page. | E13: 1.Server must be work 2..Account must be in system | F13: Passed | G13: 45978 | H13: TuanCM | I13: Passed | J13: 45980 | K13: TuanCM | L13: Passed | M13: 45981 | N13: TuanCM
A14: [Logout- 3] | B14: Register to become a lecturer | C14: 1. Enter "http://localhost:5173/" to navigate to the website. (Top-right corner of the screen) 2. Guest user click the “Đăng ký” button. 3. The site displays the registration form. 4. Guest user select a registration role: “Student” or “Lecturer.” 5. Enter the following valid information: - Email: lecturer@gmail.com - Password: Lecturer@123 - RePassword: Lecturer@123 - Full Name: Nguyen Van A 6. Guest user click the “Đăng ký” button. 7. Guest user ou are redirected to the “Đăng nhập” screen. 8. The guest user logs into the system using the newly registered account. 9. The system redirects to the Lecturer Application submission page. 10. Enter the following valid information: - Chức danh: Senior - Chuyên môn: Web Developer - Mô tả kinh nghiệm: 5 years as a software engineer - Tải lên CV: PDF file - Tải lên ảnh bằng cấp: Image file (e.g., .png, .jpg...). 11. The user clicks the “Nộp đơn ứng tuyển” button. | D14: System displays message "Nộp CV thành công! Chúng tôi sẽ liên hệ với bạn sớm." | E14: 1.Server must be work 2..Account must be in system | F14: Passed | G14: 45978 | H14: TuanCM | I14: Passed | J14: 45980 | K14: TuanCM | L14: Passed | M14: 45981 | N14: TuanCM

Sheet View user profile
A2: Feature | B2: View user profile | R2: Passed
A3: Test requirement | B3: <Brief description about requirements which are tested in this sheet> | R3: Failed
A4: Number of TCs | B4: =COUNTA(A12:A865) -> 1 | R4: Pending
A5: Testing Round | B5: Passed | C5: Failed | D5: Pending | E5: N/A | R5: N/A
A6: Round 1 | B6: =COUNTIF($F10:$F863,B5) -> 1 | C6: =COUNTIF($F10:$F863,C5) -> 0 | D6: =COUNTIF($F10:$F863,D5) -> 0 | E6: =COUNTIF($F10:$F863,E5) -> 0
A7: Round 2 | B7: =COUNTIF($F10:$F863,B5) -> 1 | C7: =COUNTIF($F10:$F863,C5) -> 0 | D7: =COUNTIF($F10:$F863,D5) -> 0 | E7: =COUNTIF($F10:$F863,E5) -> 0
A8: Round 3 | B8: =COUNTIF($F10:$F863,B5) -> 1 | C8: =COUNTIF($F10:$F863,C5) -> 0 | D8: =COUNTIF($F10:$F863,D5) -> 0 | E8: =COUNTIF($F10:$F863,E5) -> 0
A10: Test Case ID | B10: Test Case Description | C10: Test Case Procedure | D10: Expected Results | E10: Pre-conditions | F10: Round 1 | G10: Test date | H10: Tester | I10: Round 2 | J10: Test date | K10: Tester | L10: Round 3 | M10: Test date | N10: Tester | O10: Note
A11: View user profile
A12: <View Profile - 1> | B12: Test the UI display of the User Profile | C12: 1. Login system 2. Click on user profile icon right of dashboard screen | D12: 1.Home Screen is displayed 2.The UI display of the User Detail is displayed include : "Name", "Phone", "Email", "Sex", "Password", "Old Password", "New Password", Save Change Button Logout | E12: 1. Device with Internet connection | F12: Passed | G12: 45978 | H12: TuanCM | I12: Passed | J12: 45980 | K12: TuanCM | L12: Passed | M12: 45981 | N12: TuanCM

Sheet Update user profile
A2: Feature | B2: Update user profile | R2: Passed
A3: Test requirement | B3: <Brief description about requirements which are tested in this sheet> | R3: Failed
A4: Number of TCs | B4: =COUNTA(A12:A866) -> 2 | R4: Pending
A5: Testing Round | B5: Passed | C5: Failed | D5: Pending | E5: N/A | R5: N/A
A6: Round 1 | B6: =COUNTIF($F10:$F864,B5) -> 2 | C6: =COUNTIF($F10:$F864,C5) -> 0 | D6: =COUNTIF($F10:$F864,D5) -> 0 | E6: =COUNTIF($F10:$F864,E5) -> 0
A7: Round 2 | B7: =COUNTIF($F10:$F864,B5) -> 2 | C7: =COUNTIF($F10:$F864,C5) -> 0 | D7: =COUNTIF($F10:$F864,D5) -> 0 | E7: =COUNTIF($F10:$F864,E5) -> 0
A8: Round 3 | B8: =COUNTIF($F10:$F864,B5) -> 2 | C8: =COUNTIF($F10:$F864,C5) -> 0 | D8: =COUNTIF($F10:$F864,D5) -> 0 | E8: =COUNTIF($F10:$F864,E5) -> 0
A10: Test Case ID | B10: Test Case Description | C10: Test Case Procedure | D10: Expected Results | E10: Pre-conditions | F10: Round 1 | G10: Test date | H10: Tester | I10: Round 2 | J10: Test date | K10: Tester | L10: Round 3 | M10: Test date | N10: Tester | O10: Note
A11: Update user profile
A12: [Update user profile - 1] | B12: Update user profile with valid data | C12: 1. Navigate to "Thông tin cơ bản" tab 2. Update phone number to "0911178086" 3. Update name to "testgiaovien@gmail.com" 4. Update birthday to "12/12/2025" 5. Update biography field with "11111111" 6. Click "Lưu thay đổi" button | D12: - Profile is successfully updated - Success message displayed - Updated information reflects in sidebar - All fields retain new values | E12: - User is logged in - User has access to profile page | F12: Passed | G12: 45978 | H12: TuanCM | I12: Passed | J12: 45980 | K12: TuanCM | L12: Passed | M12: 45981 | N12: TuanCM
A13: [Update user profile - 2] | B13: Update profile with invalid phone number | C13: 1. Navigate to "Thông tin cơ bản" tab 2. Enter invalid phone number (e.g., "abc123") 3. Click "Lưu thay đổi" button | D13: - Validation error message appears - Profile is not updated - Invalid data is not saved to database | E13: - User is logged in - User has access to profile page | F13: Passed | G13: 45978 | H13: TuanCM | I13: Passed | J13: 45980 | K13: TuanCM | L13: Passed | M13: 45981 | N13: TuanCM

Sheet Change password
A2: Feature | B2: Change password | R2: Passed
A3: Test requirement | B3: <Brief description about requirements which are tested in this sheet> | R3: Failed
A4: Number of TCs | B4: =COUNTA(A12:A868) -> 4 | R4: Pending
A5: Testing Round | B5: Passed | C5: Failed | D5: Pending | E5: N/A | R5: N/A
A6: Round 1 | B6: =COUNTIF($F10:$F866,B5) -> 4 | C6: =COUNTIF($F10:$F866,C5) -> 0 | D6: =COUNTIF($F10:$F866,D5) -> 0 | E6: =COUNTIF($F10:$F866,E5) -> 0
A7: Round 2 | B7: =COUNTIF($F10:$F866,B5) -> 4 | C7: =COUNTIF($F10:$F866,C5) -> 0 | D7: =COUNTIF($F10:$F866,D5) -> 0 | E7: =COUNTIF($F10:$F866,E5) -> 0
A8: Round 3 | B8: =COUNTIF($F10:$F866,B5) -> 4 | C8: =COUNTIF($F10:$F866,C5) -> 0 | D8: =COUNTIF($F10:$F866,D5) -> 0 | E8: =COUNTIF($F10:$F866,E5) -> 0
A10: Test Case ID | B10: Test Case Description | C10: Test Case Procedure | D10: Expected Results | E10: Pre-conditions | F10: Round 1 | G10: Test date | H10: Tester | I10: Round 2 | J10: Test date | K10: Tester | L10: Round 3 | M10: Test date | N10: Tester | O10: Note
A11: Change password
A12: [Change password - 1] | B12: Update user profile with valid data | C12: 1. Navigate to "Đổi mật khẩu" tab 2. Enter current password in "Mật khẩu cũ" field 3. Enter new password (min 6 characters) in "Mật khẩu mới" field 4. Re-enter new password in "Xác nhận mật khẩu mới" field 5. Click "Cập nhật mật khẩu" button 6. Logout 7. Login with new password | D12: - Password updated successfully - Success message displayed - User can login with new password - Old password no longer works | E12: - User is logged in - User knows current password | F12: Passed | G12: 45978 | H12: TuanCM | I12: Passed | J12: 45980 | K12: TuanCM | L12: Passed | M12: 45981 | N12: TuanCM
A13: [Change password - 2] | B13: Change password with incorrect current password | C13: 1. Navigate to "Đổi mật khẩu" tab 2. Enter incorrect current password 3. Enter valid new password and confirmation 4. Click "Cập nhật mật khẩu" button | D13: - Error message displays: "Current password is incorrect" - Password is not changed - User can still login with old password | E13: - User is logged in | F13: Passed | G13: 45978 | H13: TuanCM | I13: Passed | J13: 45980 | K13: TuanCM | L13: Passed | M13: 45981 | N13: TuanCM
A14: [Change password - 3] | B14: Change password with mismatched confirmation | C14: 1. Navigate to "Đổi mật khẩu" tab 2. Enter correct current password 3. Enter new password in "Mật khẩu mới" 4. Enter different password in "Xác nhận mật khẩu mới" 5. Click "Cập nhật mật khẩu" button | D14: - Error message: "Passwords do not match" - Password is not changed - Form highlights mismatched fields | E14: - User is logged in | F14: Passed | G14: 45978 | H14: TuanCM | I14: Passed | J14: 45980 | K14: TuanCM | L14: Passed | M14: 45981 | N14: TuanCM
A15: [Change password - 4] | B15: Change password with less than 6 characters | C15: 1. Navigate to "Đổi mật khẩu" tab 2. Enter correct current password 3. Enter password with less than 6 characters (e.g., "12345") 4. Confirm the short password 5. Click "Cập nhật mật khẩu" button | D15: - Validation error: "Password must be at least 6 characters" - Password is not changed | E15: - User is logged in | F15: Passed | G15: 45978 | H15: TuanCM | I15: Passed | J15: 45980 | K15: TuanCM | L15: Passed | M15: 45981 | N15: TuanCM

Sheet View purchase history
A2: Feature | B2: View purchase history | R2: Passed
A3: Test requirement | B3: <Brief description about requirements which are tested in this sheet> | R3: Failed
A4: Number of TCs | B4: =COUNTA(A12:A866) -> 2 | R4: Pending
A5: Testing Round | B5: Passed | C5: Failed | D5: Pending | E5: N/A | R5: N/A
A6: Round 1 | B6: =COUNTIF($F10:$F864,B5) -> 2 | C6: =COUNTIF($F10:$F864,C5) -> 0 | D6: =COUNTIF($F10:$F864,D5) -> 0 | E6: =COUNTIF($F10:$F864,E5) -> 0
A7: Round 2 | B7: =COUNTIF($F10:$F864,B5) -> 2 | C7: =COUNTIF($F10:$F864,C5) -> 0 | D7: =COUNTIF($F10:$F864,D5) -> 0 | E7: =COUNTIF($F10:$F864,E5) -> 0
A8: Round 3 | B8: =COUNTIF($F10:$F864,B5) -> 2 | C8: =COUNTIF($F10:$F864,C5) -> 0 | D8: =COUNTIF($F10:$F864,D5) -> 0 | E8: =COUNTIF($F10:$F864,E5) -> 0
A10: Test Case ID | B10: Test Case Description | C10: Test Case Procedure | D10: Expected Results | E10: Pre-conditions | F10: Round 1 | G10: Test date | H10: Tester | I10: Round 2 | J10: Test date | K10: Tester | L10: Round 3 | M10: Test date | N10: Tester | O10: Note
A11: View purchase history
A12: [View purchase history - 1] | B12: View purchase history with multiple orders | C12: 1. Navigate to "Lịch Sử Mua Hàng" page 2. Verify page title "Lịch Sử Mua Hàng" displays 3. Verify subtitle "Xem lại các giao dịch và khoá học bạn đã mua" 4. Count number of orders displayed 5. Verify orders sorted by date (newest first) | D12: - All purchase orders display - Orders in chronological order - Each order shows date/time - Course count visible - Price and payment method shown | E12: - User is logged in - User has purchase history | F12: Passed | G12: 45978 | H12: TuanCM | I12: Passed | J12: 45980 | K12: TuanCM | L12: Passed | M12: 45981 | N12: TuanCM
A13: [View purchase history - 2] | B13: Expand order to view full details | C13: 1. Navigate to purchase history 2. Click on collapsed order (default state) 3. Verify order expands 4. Check "Thông tin giao dịch" section displays 5. Verify transaction time shown 6. Verify order code (Mã đơn hàng) displays 7. Verify "Tổng thanh toán" displays | D13: - Order expands smoothly with animation - Transaction info section visible - Order code complete - Total payment shows "10.000 đ" - Expand icon changes to collapse icon | E13: - User is logged in - User has purchases | F13: Passed | G13: 45978 | H13: TuanCM | I13: Passed | J13: 45980 | K13: TuanCM | L13: Passed | M13: 45981 | N13: TuanCM

Sheet View cart
A2: Feature | B2: View cart | R2: Passed
A3: Test requirement | B3: <Brief description about requirements which are tested in this sheet> | R3: Failed
A4: Number of TCs | B4: =COUNTA(A12:A866) -> 2 | R4: Pending
A5: Testing Round | B5: Passed | C5: Failed | D5: Pending | E5: N/A | R5: N/A
A6: Round 1 | B6: =COUNTIF($F10:$F864,B5) -> 2 | C6: =COUNTIF($F10:$F864,C5) -> 0 | D6: =COUNTIF($F10:$F864,D5) -> 0 | E6: =COUNTIF($F10:$F864,E5) -> 0
A7: Round 2 | B7: =COUNTIF($F10:$F864,B5) -> 2 | C7: =COUNTIF($F10:$F864,C5) -> 0 | D7: =COUNTIF($F10:$F864,D5) -> 0 | E7: =COUNTIF($F10:$F864,E5) -> 0
A8: Round 3 | B8: =COUNTIF($F10:$F864,B5) -> 2 | C8: =COUNTIF($F10:$F864,C5) -> 0 | D8: =COUNTIF($F10:$F864,D5) -> 0 | E8: =COUNTIF($F10:$F864,E5) -> 0
A10: Test Case ID | B10: Test Case Description | C10: Test Case Procedure | D10: Expected Results | E10: Pre-conditions | F10: Round 1 | G10: Test date | H10: Tester | I10: Round 2 | J10: Test date | K10: Tester | L10: Round 3 | M10: Test date | N10: Tester | O10: Note
A11: View cart
A12: [View cart - 1] | B12: View cart with multiple items | C12: 1. Add 3 different courses to cart 2. Navigate to cart page 3. Verify all items displayed 4. Verify total count shows "3 khóa học trong giỏ hàng" 5. Verify total price is sum of all items | D12: - All items listed separately - Each item shows complete info - Count accurate - Total calculation correct - Scrollable if needed | E12: - User is logged in - Multiple courses available | F12: Passed | G12: 45978 | H12: TuanCM | I12: Passed | J12: 45980 | K12: TuanCM | L12: Passed | M12: 45981 | N12: TuanCM
A13: [View cart - 1] | B13: View empty cart | C13: 1. Navigate to "Giỏ hàng" page 2. Verify empty state displays | D13: - Empty cart message shown - No items displayed - Suggestion to browse courses - Checkout button hidden/disabled - Cart badge shows "0" or hidden | E13: - User is logged in - Cart is empty | F13: Passed | G13: 45978 | H13: TuanCM | I13: Passed | J13: 45980 | K13: TuanCM | L13: Passed | M13: 45981 | N13: TuanCM

Sheet Add to cart
A2: Feature | B2: Add to cart | R2: Passed
A3: Test requirement | B3: <Brief description about requirements which are tested in this sheet> | R3: Failed
A4: Number of TCs | B4: =COUNTA(A12:A867) -> 3 | R4: Pending
A5: Testing Round | B5: Passed | C5: Failed | D5: Pending | E5: N/A | R5: N/A
A6: Round 1 | B6: =COUNTIF($F10:$F865,B5) -> 3 | C6: =COUNTIF($F10:$F865,C5) -> 0 | D6: =COUNTIF($F10:$F865,D5) -> 0 | E6: =COUNTIF($F10:$F865,E5) -> 0
A7: Round 2 | B7: =COUNTIF($F10:$F865,B5) -> 3 | C7: =COUNTIF($F10:$F865,C5) -> 0 | D7: =COUNTIF($F10:$F865,D5) -> 0 | E7: =COUNTIF($F10:$F865,E5) -> 0
A8: Round 3 | B8: =COUNTIF($F10:$F865,B5) -> 3 | C8: =COUNTIF($F10:$F865,C5) -> 0 | D8: =COUNTIF($F10:$F865,D5) -> 0 | E8: =COUNTIF($F10:$F865,E5) -> 0
A10: Test Case ID | B10: Test Case Description | C10: Test Case Procedure | D10: Expected Results | E10: Pre-conditions | F10: Round 1 | G10: Test date | H10: Tester | I10: Round 2 | J10: Test date | K10: Tester | L10: Round 3 | M10: Test date | N10: Tester | O10: Note
A11: Add to cart
A12: [Add to cart - 1] | B12: Add course to cart from course page | C12: 1. Navigate to course detail page 2. Verify "Add to Cart" button visible 3. Click "Add to Cart" button 4. Verify success notification 5. Check cart icon badge increments 6. Navigate to cart to verify item added | D12: - Success message: "Course added to cart" - Cart badge increments by 1 - Item appears in cart - Course details correct in cart - Price matches course price | E12: - User is logged in - Course not in cart - Course not already owned | F12: Passed | G12: 45978 | H12: TuanCM | I12: Passed | J12: 45980 | K12: TuanCM | L12: Passed | M12: 45981 | N12: TuanCM
A13: [Add to cart - 2] | B13: Add multiple different courses to cart | C13: 1. Add first course to cart 2. Navigate to different course 3. Add second course to cart 4. Navigate to third course 5. Add third course to cart 6. Verify cart count shows "3" | D13: - Each course added successfully - Cart badge increments each time - All courses visible in cart - No duplicates - Total price = sum of all courses | E13: - User is logged in - Multiple courses available - Courses not owned | F13: Passed | G13: 45978 | H13: TuanCM | I13: Passed | J13: 45980 | K13: TuanCM | L13: Passed | M13: 45981 | N13: TuanCM
A14: [Add to cart - 3] | B14: Attempt to add already owned course | C14: 1. Navigate to course user already purchased 2. Verify "Add to Cart" button status 3. Attempt to add to cart | D14: - Button shows disabled - Course cannot be added - Cart not modified | E14: - User is logged in - User owns the course | F14: Passed | G14: 45978 | H14: TuanCM | I14: Passed | J14: 45980 | K14: TuanCM | L14: Passed | M14: 45981 | N14: TuanCM

Sheet Remove item from cart
A2: Feature | B2: Remove item from cart | R2: Passed
A3: Test requirement | B3: <Brief description about requirements which are tested in this sheet> | R3: Failed
A4: Number of TCs | B4: =COUNTA(A12:A866) -> 2 | R4: Pending
A5: Testing Round | B5: Passed | C5: Failed | D5: Pending | E5: N/A | R5: N/A
A6: Round 1 | B6: =COUNTIF($F10:$F864,B5) -> 2 | C6: =COUNTIF($F10:$F864,C5) -> 0 | D6: =COUNTIF($F10:$F864,D5) -> 0 | E6: =COUNTIF($F10:$F864,E5) -> 0
A7: Round 2 | B7: =COUNTIF($F10:$F864,B5) -> 2 | C7: =COUNTIF($F10:$F864,C5) -> 0 | D7: =COUNTIF($F10:$F864,D5) -> 0 | E7: =COUNTIF($F10:$F864,E5) -> 0
A8: Round 3 | B8: =COUNTIF($F10:$F864,B5) -> 2 | C8: =COUNTIF($F10:$F864,C5) -> 0 | D8: =COUNTIF($F10:$F864,D5) -> 0 | E8: =COUNTIF($F10:$F864,E5) -> 0
A10: Test Case ID | B10: Test Case Description | C10: Test Case Procedure | D10: Expected Results | E10: Pre-conditions | F10: Round 1 | G10: Test date | H10: Tester | I10: Round 2 | J10: Test date | K10: Tester | L10: Round 3 | M10: Test date | N10: Tester | O10: Note
A11: Remove item from cart
A12: [Remove item from cart - 1] | B12: Remove single item from cart | C12: 1. Navigate to cart with 1 item 2. Click "Xóa" button on course 3. Confirm removal if prompted 4. Verify item removed | D12: - Confirmation dialog appears - Item removed from cart - Cart badge decrements to "0" - Total price updates to "0 đ" - Empty cart message displays | E12: - User is logged in - Cart has 1 item | F12: Passed | G12: 45978 | H12: TuanCM | I12: Passed | J12: 45980 | K12: TuanCM | L12: Passed | M12: 45981 | N12: TuanCM
A13: [Remove item from cart - 1] | B13: Remove last item in cart | C13: 1. Navigate to cart with 1 item 2. Click "Xóa" button 3. Confirm removal 4. Verify cart becomes empty | D13: - Item removed - Cart badge shows "0" | E13: - User is logged in - Cart has exactly 1 item | F13: Passed | G13: 45978 | H13: TuanCM | I13: Passed | J13: 45980 | K13: TuanCM | L13: Passed | M13: 45981 | N13: TuanCM

Sheet Add course
A2: Feature | B2: Add course | R2: Passed
A3: Test requirement | B3: <Brief description about requirements which are tested in this sheet> | R3: Failed
A4: Number of TCs | B4: =COUNTA(A12:A866) -> 2 | R4: Pending
A5: Testing Round | B5: Passed | C5: Failed | D5: Pending | E5: N/A | R5: N/A
A6: Round 1 | B6: =COUNTIF($F10:$F864,B5) -> 2 | C6: =COUNTIF($F10:$F864,C5) -> 0 | D6: =COUNTIF($F10:$F864,D5) -> 0 | E6: =COUNTIF($F10:$F864,E5) -> 0
A7: Round 2 | B7: =COUNTIF($F10:$F864,B5) -> 2 | C7: =COUNTIF($F10:$F864,C5) -> 0 | D7: =COUNTIF($F10:$F864,D5) -> 0 | E7: =COUNTIF($F10:$F864,E5) -> 0
A8: Round 3 | B8: =COUNTIF($F10:$F864,B5) -> 2 | C8: =COUNTIF($F10:$F864,C5) -> 0 | D8: =COUNTIF($F10:$F864,D5) -> 0 | E8: =COUNTIF($F10:$F864,E5) -> 0
A10: Test Case ID | B10: Test Case Description | C10: Test Case Procedure | D10: Expected Results | E10: Pre-conditions | F10: Round 1 | G10: Test date | H10: Tester | I10: Round 2 | J10: Test date | K10: Tester | L10: Round 3 | M10: Test date | N10: Tester | O10: Note
A11: Add course
A12: [Add course - 1] | B12: Create course with all required fields | C12: 1. Click "Tạo khóa học mới" button 2. Enter course name: "React Advanced Patterns" in "Tên khóa học" field 3. Enter description in "Mô tả khóa học" field 4. Select category from "Danh mục" dropdown 5. Select subcategory from "Danh mục con" dropdown 6. Toggle "AI hỗ trợ học viên" if needed 7. Upload course image via "Chọn ảnh" 8. Click "Tạo khóa học" button | D12: - Course created successfully - Success notification displayed - Modal closes - New course appears in course list with "Nháp" (Draft) status - Course saved in database - Creator can see the course in list | E12: - User is logged in - User has permissions | F12: Passed | G12: 45978 | H12: TuanCM | I12: Passed | J12: 45980 | K12: TuanCM | L12: Passed | M12: 45981 | N12: TuanCM
A13: [Add course - 2] | B13: Create course with missing required fields | C13: 1. Click "Tạo khóa học mới" button 2. Enter course name 3. Leave "Mô tả khóa học" field empty (required field marked with *) 4. Fill other fields 5. Click "Tạo khóa học" button | D13: - Validation error displays - Description field highlighted - Error message shown - Form not submitted - Modal remains open | E13: - User is logged in - User has permissions | F13: Passed | G13: 45978 | H13: TuanCM | I13: Passed | J13: 45980 | K13: TuanCM | L13: Passed | M13: 45981 | N13: TuanCM

Sheet Hide course
A2: Feature | B2: Hide course | R2: Passed
A3: Test requirement | B3: <Brief description about requirements which are tested in this sheet> | R3: Failed
A4: Number of TCs | B4: =COUNTA(A12:A865) -> 1 | R4: Pending
A5: Testing Round | B5: Passed | C5: Failed | D5: Pending | E5: N/A | R5: N/A
A6: Round 1 | B6: =COUNTIF($F10:$F863,B5) -> 1 | C6: =COUNTIF($F10:$F863,C5) -> 0 | D6: =COUNTIF($F10:$F863,D5) -> 0 | E6: =COUNTIF($F10:$F863,E5) -> 0
A7: Round 2 | B7: =COUNTIF($F10:$F863,B5) -> 1 | C7: =COUNTIF($F10:$F863,C5) -> 0 | D7: =COUNTIF($F10:$F863,D5) -> 0 | E7: =COUNTIF($F10:$F863,E5) -> 0
A8: Round 3 | B8: =COUNTIF($F10:$F863,B5) -> 1 | C8: =COUNTIF($F10:$F863,C5) -> 0 | D8: =COUNTIF($F10:$F863,D5) -> 0 | E8: =COUNTIF($F10:$F863,E5) -> 0
A10: Test Case ID | B10: Test Case Description | C10: Test Case Procedure | D10: Expected Results | E10: Pre-conditions | F10: Round 1 | G10: Test date | H10: Tester | I10: Round 2 | J10: Test date | K10: Tester | L10: Round 3 | M10: Test date | N10: Tester | O10: Note
A11: Hide course
A12: [Hide course - 1] | B12: Hide a published course | C12: 1. Navigate to course list 2. Locate published course "Khoá học test 12" 3. Click hide button (eye-slash icon in red) 4. Confirm action if prompted 5. Verify course hidden | D12: - Confirmation dialog appears - Course status changes from "Xuất bản" to "Đã ẩn" - Status badge updates - Course moves to "Đã ẩn" tab - "Đã xuất bản" count decreases by 1 (29 → 28) - "Đã ẩn" count increases by 1 (7 → 8) | E12: - User is logged in - User has permissions | F12: Passed | G12: 45978 | H12: TuanCM | I12: Passed | J12: 45980 | K12: TuanCM | L12: Passed | M12: 45981 | N12: TuanCM

Sheet Update course - general
A2: Feature | B2: Update course | R2: Passed
A3: Test requirement | B3: <Brief description about requirements which are tested in this sheet> | R3: Failed
A4: Number of TCs | B4: =COUNTA(A12:A873) -> 9 | R4: Pending
A5: Testing Round | B5: Passed | C5: Failed | D5: Pending | E5: N/A | R5: N/A
A6: Round 1 | B6: =COUNTIF($F10:$F871,B5) -> 9 | C6: =COUNTIF($F10:$F871,C5) -> 0 | D6: =COUNTIF($F10:$F871,D5) -> 0 | E6: =COUNTIF($F10:$F871,E5) -> 0
A7: Round 2 | B7: =COUNTIF($F10:$F871,B5) -> 9 | C7: =COUNTIF($F10:$F871,C5) -> 0 | D7: =COUNTIF($F10:$F871,D5) -> 0 | E7: =COUNTIF($F10:$F871,E5) -> 0
A8: Round 3 | B8: =COUNTIF($F10:$F871,B5) -> 9 | C8: =COUNTIF($F10:$F871,C5) -> 0 | D8: =COUNTIF($F10:$F871,D5) -> 0 | E8: =COUNTIF($F10:$F871,E5) -> 0
A10: Test Case ID | B10: Test Case Description | C10: Test Case Procedure | D10: Expected Results | E10: Pre-conditions | F10: Round 1 | G10: Test date | H10: Tester | I10: Round 2 | J10: Test date | K10: Tester | L10: Round 3 | M10: Test date | N10: Tester | O10: Note
A11: Update course
A12: [Update course - 1] | B12: View course basic information form fields | C12: 1. Navigate to course edit page 2. Verify all fields display with current values | D12: - All fields are filled - All fields editable | E12: - User is logged in - Course exists - On edit page | F12: Passed | G12: 45978 | H12: TuanCM | I12: Passed | J12: 45980 | K12: TuanCM | L12: Passed | M12: 45981 | N12: TuanCM
A13: [Update course - 2] | B13: Update multiple fields simultaneously | C13: 1. Navigate to course edit page 2. Update title to "New Course Title" 3. Update description to "New detailed description" 4. Change category 5. Change parent category 6. Upload new image 7. Click "Lưu thay đổi" button | D13: - All fields accept changes - All updates save successfully - Success notification displays - All changes persist in database - Course list reflects all changes - No data loss | E13: - User is logged in - Course exists - On edit page | F13: Passed | G13: 45978 | H13: TuanCM | I13: Passed | J13: 45980 | K13: TuanCM | L13: Passed | M13: 45981 | N13: TuanCM
A14: [Update course - 3] | B14: View current course price | C14: 1. Navigate to pricing page 2. Locate current price section 3. Verify display | D14: - "Giá hiện tại" section displays with green background - Shows "100.000đ" - Dollar icon in green circle - Note text: "Học viên cần thanh toán để đăng ký" - Price formatted with đ currency symbol - Prominent display | E14: - User is logged in - On pricing page - Course has price set | F14: Passed | G14: 45978 | H14: TuanCM | I14: Passed | J14: 45980 | K14: TuanCM | L14: Passed | M14: 45981 | N14: TuanCM
A15: [Update course - 4] | B15: View price type options (Free vs Paid) | C15: 1. Navigate to pricing page 2. Locate "Loại giá" section 3. Verify radio button options | D15: - Two radio button options visible - Option 1: "Miễn phí" with subtitle "Không yêu cầu thanh toán" - Option 2: "Trả phí" with subtitle "Yêu cầu thanh toán" - "Trả phí" currently selected - Radio buttons functional - Can toggle between options | E15: - User is logged in - On pricing page | F15: Passed | G15: 45978 | H15: TuanCM | I15: Passed | J15: 45980 | K15: TuanCM | L15: Passed | M15: 45981 | N15: TuanCM
A16: [Update course - 5] | B16: Change course from paid to free | C16: 1. Navigate to pricing page 2. Current price is "100.000đ" (paid) 3. Select "Miễn phí" radio button 4. Click "Lưu thay đổi" button 5. Verify update | D16: - "Miễn phí" radio button selected - Price field disabled or hidden - Success notification displays - Course price updates to 0đ in database - Current price section updates to show "Miễn phí" - Students can enroll without payment - Changes persist | E16: - User is logged in - On pricing page - Course currently paid | F16: Passed | G16: 45978 | H16: TuanCM | I16: Passed | J16: 45980 | K16: TuanCM | L16: Passed | M16: 45981 | N16: TuanCM
A17: [Update course - 6] | B17: Change course from free to paid | C17: 1. Navigate to pricing page with free course 2. Select "Trả phí" radio button 3. Enter price in "Giá khóa học (VNĐ)" field 4. Click "Lưu thay đổi" button 5. Verify update | D17: - "Trả phí" radio button selected - Price input field becomes enabled - Can enter price value - Success notification displays - Course requires payment - Current price updates - Students must pay to enroll - Changes persist | E17: - User is logged in - On pricing page - Course currently free | F17: Passed | G17: 45978 | H17: TuanCM | I17: Passed | J17: 45980 | K17: TuanCM | L17: Passed | M17: 45981 | N17: TuanCM
A18: [Update course - 7] | B18: Update course price value | C18: 1. Navigate to pricing page 2. Ensure "Trả phí" selected 3. Click in "Giá khóa học (VNĐ)" field (currently 100000) 4. Clear value and enter "150000" 5. Click "Lưu thay đổi" button 6. Verify price updates | D18: - Price field accepts numeric input - Old value cleared - New value "150000" entered - Display shows "Giá hiện thi: 100.000đ" updates to "150. 000đ" - Success notification - Price updated in database - Course shows new price - Changes persist | E18: - User is logged in - On pricing page - "Trả phí" selected | F18: Passed | G18: 45978 | H18: TuanCM | I18: Passed | J18: 45980 | K18: TuanCM | L18: Passed | M18: 45981 | N18: TuanCM
A19: [Update course - 8] | B19: Enter invalid price (negative number) | C19: 1. Navigate to pricing page 2. Select "Trả phí" 3. Enter negative price "-50000" 4. Click "Lưu thay đổi" button | D19: - Validation error displays - Error message: "Price must be positive" or similar - Field highlighted - Form not submitted - Price not updated - Clear error feedback | E19: - User is logged in - On pricing page | F19: Passed | G19: 45978 | H19: TuanCM | I19: Passed | J19: 45980 | K19: TuanCM | L19: Passed | M19: 45981 | N19: TuanCM
A20: [Update course - 9] | B20: Enter invalid price (non-numeric) | C20: 1. Navigate to pricing page 2. Select "Trả phí" 3. Enter text "abc" or special chars 4. Attempt to save | D20: - Validation error displays - Field may prevent non-numeric input - Form not submitted - Price not updated | E20: - User is logged in - On pricing page | F20: Passed | G20: 45978 | H20: TuanCM | I20: Passed | J20: 45980 | K20: TuanCM | L20: Passed | M20: 45981 | N20: TuanCM

Sheet View sections
A2: Feature | B2: View sections | R2: Passed
A3: Test requirement | B3: <Brief description about requirements which are tested in this sheet> | R3: Failed
A4: Number of TCs | B4: =COUNTA(A12:A866) -> 2 | R4: Pending
A5: Testing Round | B5: Passed | C5: Failed | D5: Pending | E5: N/A | R5: N/A
A6: Round 1 | B6: =COUNTIF($F10:$F864,B5) -> 2 | C6: =COUNTIF($F10:$F864,C5) -> 0 | D6: =COUNTIF($F10:$F864,D5) -> 0 | E6: =COUNTIF($F10:$F864,E5) -> 0
A7: Round 2 | B7: =COUNTIF($F10:$F864,B5) -> 2 | C7: =COUNTIF($F10:$F864,C5) -> 0 | D7: =COUNTIF($F10:$F864,D5) -> 0 | E7: =COUNTIF($F10:$F864,E5) -> 0
A8: Round 3 | B8: =COUNTIF($F10:$F864,B5) -> 2 | C8: =COUNTIF($F10:$F864,C5) -> 0 | D8: =COUNTIF($F10:$F864,D5) -> 0 | E8: =COUNTIF($F10:$F864,E5) -> 0
A10: Test Case ID | B10: Test Case Description | C10: Test Case Procedure | D10: Expected Results | E10: Pre-conditions | F10: Round 1 | G10: Test date | H10: Tester | I10: Round 2 | J10: Test date | K10: Tester | L10: Round 3 | M10: Test date | N10: Tester | O10: Note
A11: View sections
A12: [View sections - 1] | B12: View section list with multiple sections | C12: 1. Navigate to "Nội dung khóa học" page 2. Verify sections display 3. Check section count | D12: - Two sections display: "Chương 1" and "Chương 2" - Section count at top shows "2 chương" - Each section has numbered circle (1, 2) - Section names visible - Item counts show "4 mục" and "2 mục" - Edit, delete, and expand icons visible on each section | E12: - User is logged in - On sections page | F12: Passed | G12: 45978 | H12: TuanCM | I12: Passed | J12: 45980 | K12: TuanCM | L12: Passed | M12: 45981 | N12: TuanCM
A13: [View sections - 2] | B13: View empty sections page | C13: 1. Navigate to sections page for course with no sections 2. Verify empty state | D13: - Empty state message displays - Message suggests creating first section - "Chương mới" button visible - Section count shows "0 chương" | E13: - User is logged in - On sections page | F13: Passed | G13: 45978 | H13: TuanCM | I13: Passed | J13: 45980 | K13: TuanCM | L13: Passed | M13: 45981 | N13: TuanCM

Sheet Add sections
A2: Feature | B2: Add sections | R2: Passed
A3: Test requirement | B3: <Brief description about requirements which are tested in this sheet> | R3: Failed
A4: Number of TCs | B4: =COUNTA(A12:A868) -> 4 | R4: Pending
A5: Testing Round | B5: Passed | C5: Failed | D5: Pending | E5: N/A | R5: N/A
A6: Round 1 | B6: =COUNTIF($F10:$F866,B5) -> 4 | C6: =COUNTIF($F10:$F866,C5) -> 0 | D6: =COUNTIF($F10:$F866,D5) -> 0 | E6: =COUNTIF($F10:$F866,E5) -> 0
A7: Round 2 | B7: =COUNTIF($F10:$F866,B5) -> 4 | C7: =COUNTIF($F10:$F866,C5) -> 0 | D7: =COUNTIF($F10:$F866,D5) -> 0 | E7: =COUNTIF($F10:$F866,E5) -> 0
A8: Round 3 | B8: =COUNTIF($F10:$F866,B5) -> 4 | C8: =COUNTIF($F10:$F866,C5) -> 0 | D8: =COUNTIF($F10:$F866,D5) -> 0 | E8: =COUNTIF($F10:$F866,E5) -> 0
A10: Test Case ID | B10: Test Case Description | C10: Test Case Procedure | D10: Expected Results | E10: Pre-conditions | F10: Round 1 | G10: Test date | H10: Tester | I10: Round 2 | J10: Test date | K10: Tester | L10: Round 3 | M10: Test date | N10: Tester | O10: Note
A11: Add sections
A12: [Add sections - 1] | B12: Create section with title and description | C12: 1. Click "Chương mới" button 2. Enter title "Advanced Topics" 3. Enter description "This chapter covers advanced programming concepts" 4. Click "Lưu" button 5. Verify section created | D12: - Both fields accept input - Success notification displays - Section created successfully - Title and description saved - New section appears in list - Description accessible when expanded - Changes persist | E12: - User is logged in - On sections page | F12: Passed | G12: 45978 | H12: TuanCM | I12: Passed | J12: 45980 | K12: TuanCM | L12: Passed | M12: 45981 | N12: TuanCM
A13: [Add sections - 2] | B13: Create section with empty title | C13: 1. Click "Chương mới" button 2. Leave title field empty 3. Enter or leave description empty 4. Click "Lưu" button | D13: - Validation error displays - Error message near title field - Title field highlighted - Form not submitted - Section not created - Must enter title to proceed | E13: - User is logged in - Add section form open | F13: Passed | G13: 45978 | H13: TuanCM | I13: Passed | J13: 45980 | K13: TuanCM | L13: Passed | M13: 45981 | N13: TuanCM
A14: [Add sections - 3] | B14: Create section with very long title | C14: 1. Click "Chương mới" button 2. Enter very long title (e.g., 500 characters) 3. Click "Lưu" button | D14: - Validation error | E14: - User is logged in - Add section form open | F14: Passed | G14: 45978 | H14: TuanCM | I14: Passed | J14: 45980 | K14: TuanCM | L14: Passed | M14: 45981 | N14: TuanCM
A15: [Add sections - 4] | B15: Create section with special characters in title | C15: 1. Click "Chương mới" button 2. Enter title with special characters "Chương 1: C++ & Data Structures!" 3. Click "Lưu" button | D15: - Special characters accepted - No encoding issues - Section created successfully - Title displays correctly - No system errors | E15: - User is logged in - Add section form open | F15: Passed | G15: 45978 | H15: TuanCM | I15: Passed | J15: 45980 | K15: TuanCM | L15: Passed | M15: 45981 | N15: TuanCM

Sheet Update sections
A2: Feature | B2: Update sections | R2: Passed
A3: Test requirement | B3: <Brief description about requirements which are tested in this sheet> | R3: Failed
A4: Number of TCs | B4: =COUNTA(A12:A867) -> 3 | R4: Pending
A5: Testing Round | B5: Passed | C5: Failed | D5: Pending | E5: N/A | R5: N/A
A6: Round 1 | B6: =COUNTIF($F10:$F865,B5) -> 3 | C6: =COUNTIF($F10:$F865,C5) -> 0 | D6: =COUNTIF($F10:$F865,D5) -> 0 | E6: =COUNTIF($F10:$F865,E5) -> 0
A7: Round 2 | B7: =COUNTIF($F10:$F865,B5) -> 3 | C7: =COUNTIF($F10:$F865,C5) -> 0 | D7: =COUNTIF($F10:$F865,D5) -> 0 | E7: =COUNTIF($F10:$F865,E5) -> 0
A8: Round 3 | B8: =COUNTIF($F10:$F865,B5) -> 3 | C8: =COUNTIF($F10:$F865,C5) -> 0 | D8: =COUNTIF($F10:$F865,D5) -> 0 | E8: =COUNTIF($F10:$F865,E5) -> 0
A10: Test Case ID | B10: Test Case Description | C10: Test Case Procedure | D10: Expected Results | E10: Pre-conditions | F10: Round 1 | G10: Test date | H10: Tester | I10: Round 2 | J10: Test date | K10: Tester | L10: Round 3 | M10: Test date | N10: Tester | O10: Note
A11: Update sections
A12: [Update sections - 1] | B12: Update section title | C12: 1. Click edit on section 2. Change title from "Chương 1" to "Chương 1: Introduction to Programming" 3. Click "Lưu" button 4. Verify update | D12: - Title field accepts new text - Success notification displays - Section title updates in list - Shows new title "Chương 1: Introduction to Programming" - Database updated - Changes persist after refresh | E12: - User is logged in - On sections page | F12: Passed | G12: 45978 | H12: TuanCM | I12: Passed | J12: 45980 | K12: TuanCM | L12: Passed | M12: 45981 | N12: TuanCM
A13: [Update sections - 2] | B13: Update section description | C13: 1. Click edit on section 2. Click in description field 3. Enter or update description text 4. Click "Lưu" button 5. Verify update | D13: - Description field accepts input - Multi-line text supported - Success notification displays - Description updated - Can view updated description when section expanded - Changes persist | E13: - User is logged in - On sections page | F13: Passed | G13: 45978 | H13: TuanCM | I13: Passed | J13: 45980 | K13: TuanCM | L13: Passed | M13: 45981 | N13: TuanCM
A14: [Update sections - 3] | B14: Update both title and description | C14: 1. Click edit on section 2. Change title to "Updated Chapter 1" 3. Change description to "New description text" 4. Click "Lưu" button 5. Verify both updates | D14: - Both fields accept changes - Success notification displays - Both title and description updated - Changes reflected in list - Database updated for both - Changes persist | E14: - User is logged in - On sections page | F14: Passed | G14: 45978 | H14: TuanCM | I14: Passed | J14: 45980 | K14: TuanCM | L14: Passed | M14: 45981 | N14: TuanCM

Sheet Delete sections
A2: Feature | B2: Delete sections | R2: Passed
A3: Test requirement | B3: <Brief description about requirements which are tested in this sheet> | R3: Failed
A4: Number of TCs | B4: =COUNTA(A12:A865) -> 1 | R4: Pending
A5: Testing Round | B5: Passed | C5: Failed | D5: Pending | E5: N/A | R5: N/A
A6: Round 1 | B6: =COUNTIF($F10:$F863,B5) -> 1 | C6: =COUNTIF($F10:$F863,C5) -> 0 | D6: =COUNTIF($F10:$F863,D5) -> 0 | E6: =COUNTIF($F10:$F863,E5) -> 0
A7: Round 2 | B7: =COUNTIF($F10:$F863,B5) -> 1 | C7: =COUNTIF($F10:$F863,C5) -> 0 | D7: =COUNTIF($F10:$F863,D5) -> 0 | E7: =COUNTIF($F10:$F863,E5) -> 0
A8: Round 3 | B8: =COUNTIF($F10:$F863,B5) -> 1 | C8: =COUNTIF($F10:$F863,C5) -> 0 | D8: =COUNTIF($F10:$F863,D5) -> 0 | E8: =COUNTIF($F10:$F863,E5) -> 0
A10: Test Case ID | B10: Test Case Description | C10: Test Case Procedure | D10: Expected Results | E10: Pre-conditions | F10: Round 1 | G10: Test date | H10: Tester | I10: Round 2 | J10: Test date | K10: Tester | L10: Round 3 | M10: Test date | N10: Tester | O10: Note
A11: Delete sections
