Workbook
Name ACTION: #REF!
Name ACTION: #REF!

Sheet Cover
B2: SYSTEM TEST REPORT DOCUMENT
A4: Project Name | B4: Online Learning Platform – SkillUp | E4: Creator | F4: TuanCM
A5: Project Code | B5: OLP-SkillUp | E5: Issue Date | F5: 45998
A6: Document Code | B6: =B5&"_"&"System_Test_Report"&"" -> OLP-SkillUp_System_Test_Report | E6: Version | F6: 1.0
A9: Record of change
A10: Effective Date | B10: Version | C10: Change Item | D10: *A,D,M | E10: Change description | F10: Reference
A11: 45998 | B11: 1.0 | D11: A | E11: Initialize System Test
A12: 45998 | B12: 1.0 | C12: Test Cases, Test Statistics | D12: A | E12: Implement test cases for Iteration 1.
A13: 46001 | B13: 1.0 | C13: Test Cases, Test Statistics | D13: M | E13: Implement test cases for Iteration 2.
A14: 46003 | B14: 1.0 | C14: Test Cases, Test Statistics | D14: M | E14: Implement test cases for Iteration 3.

Sheet Test Cases
D1: TEST CASE LIST
B3: Project Name | D3: Online Learning Platform – SkillUp
B4: Project Code | D4: OLP-SkillUp
B5: Test Environment Setup Description | D5: 1. Server 2. SQLServer 3.Google Chrome, Microsoft Edge 4. Microsoft Visual Studio
B8: No | C8: Function Name | D8: Sheet Name | E8: Description | F8: Pre-Condition
B9: 1 | C9: Authentication | D9: Authentication
B10: 2 | C10: Workflow of Student | D10: Workflow of Student
B11: 3 | C11: Workflow of Lecturer | D11: Workflow of Lecturer
B12: 4 | C12: Workflow of System Moderator | D12: Workflow of System Moderator
B13: 5 | C13: Workflow of Content Morderator | D13: Workflow of Content Morderator
B14: 6 | C14: Workflow of Admin | D14: Workflow of Admin
B15: 7 | C15: AI Assistant | D15: AI Assistant

Sheet Test Statistics
B1: TEST STATISTICS
B3: Project Name | C3: Online Learning Platform – SkillUp | E3: Creator | H3: TuanCM
B4: Project Code | C4: OLP-SkillUp | E4: Reviewer/Approver
B5: Document Code | C5: =C4&"_"&"System_Test_Report"&"" -> OLP-SkillUp_System_Test_Report | E5: Issue Date | H5: 45998
B6: Notes
B10: No | C10: Module code | D10: Passed | E10: Failed | F10: Pending | G10: N/A | H10: Number of test cases
B11: 1 | C11: =Authentication!B2 -> Authentication | D11: =Authentication!B8 -> 15 | E11: =Authentication!C8 -> 0 | F11: =Authentication!D6 -> 0 | G11: =Authentication!E6 -> 0 | H11: =Authentication!B4 -> 15
B12: 2 | C12: ='Workflow of System Moderator'!B2 -> Workflow of System Moderator | D12: ='Workflow of System Moderator'!B6 -> 15 | E12: ='Workflow of System Moderator'!C6 -> 0 | F12: ='Workflow of System Moderator'!D6 -> 0 | G12: ='Workflow of System Moderator'!E6 -> 0 | H12: ='Workflow of System Moderator'!B4 -> 15
B13: 3 | C13: ='Workflow of Content Morderator'!B2 -> Workflow of Content Moderator | D13: ='Workflow of Content Morderator'!B6 -> 32 | E13: ='Workflow of Content Morderator'!C6 -> 0 | F13: ='Workflow of Content Morderator'!D6 -> 0 | G13: ='Workflow of Content Morderator'!E6 -> 0 | H13: ='Workflow of Content Morderator'!B4 -> 32
B14: 4 | C14: ='Workflow of Lecturer'!B2 -> Workflow of Lecturer | D14: ='Workflow of Lecturer'!B6 -> 63 | E14: ='Workflow of Lecturer'!C6 -> 0 | F14: ='Workflow of Lecturer'!D6 -> 0 | G14: ='Workflow of Lecturer'!E6 -> 0 | H14: ='Workflow of Lecturer'!B4 -> 63
B15: 5 | C15: ='Workflow of Student'!B2 -> Workflow of Student | D15: ='Workflow of Student'!B6 -> 33 | E15: ='Workflow of Student'!C6 -> 0 | F15: ='Workflow of Student'!D6 -> 0 | G15: ='Workflow of Student'!E6 -> 0 | H15: ='Workflow of Student'!B4 -> 33
B16: 6 | C16: ='Workflow of Admin'!B2 -> Workflow of Admin | D16: ='Workflow of Admin'!B6 -> 16 | E16: ='Workflow of Admin'!C6 -> 0 | F16: ='Workflow of Admin'!D6 -> 0 | G16: ='Workflow of Admin'!E6 -> 0 | H16: ='Workflow of Admin'!B4 -> 16
B17: 7 | C17: ='AI Assistant'!B2 -> AI assistant | D17: ='AI Assistant'!B6 -> 5 | E17: ='AI Assistant'!C6 -> 0 | F17: ='AI Assistant'!D6 -> 0 | G17: ='AI Assistant'!E6 -> 0 | H17: ='AI Assistant'!B4 -> 5
C19: Sub total | D19: =SUM(D9:D16) -> 174 | E19: =SUM(E9:E16) -> 0 | F19: =SUM(F9:F16) -> 0 | G19: =SUM(G9:G16) -> 0 | H19: =SUM(H9:H16) -> 174
C21: Test coverage | E21: =(D19+E19)*100/(H19-G19) -> 100 | F21: %
C22: Test successful coverage | E22: =D19*100/(H19-G19) -> 100 | F22: %

Sheet Authentication
A2: Workflow | B2: Authentication | R2: Passed
A3: Test requirement | B3: Check if the functionalities of authentication feature work. | R3: Failed
A4: Number of TCs | B4: 15 | R4: Pending
A5: Testing Round | B5: Passed | C5: Failed | D5: Pending | E5: N/A | R5: N/A
A6: Round 1 | B6: =COUNTIF($F10:$F1008,B5) -> 14 | C6: =COUNTIF($F10:$F1008,C5) -> 1 | D6: =COUNTIF($F10:$F1008,D5) -> 0 | E6: =COUNTIF($F10:$F1008,E5) -> 0
A7: Round 2 | B7: =COUNTIF($I10:$I1008,B5) -> 15 | C7: =COUNTIF($I10:$I1008,C5) -> 0 | D7: =COUNTIF($F10:$F1008,D5) -> 0 | E7: =COUNTIF($F10:$F1008,E5) -> 0
A8: Round 3 | B8: =COUNTIF($L10:$L1008,B5) -> 15 | C8: =COUNTIF($L10:$L1008,C5) -> 0 | D8: =COUNTIF($F10:$F1008,D5) -> 0 | E8: =COUNTIF($F10:$F1008,E5) -> 0
A10: Test Case ID | B10: Test Case Description | C10: Test Case Procedure | D10: Expected Results | E10: Pre-conditions | F10: Round 1 | G10: Test date | H10: Tester | I10: Round 2 | J10: Test date | K10: Tester | L10: Round 3 | M10: Test date | N10: Tester | O10: Note
A11: Register
A12: [Authen - 1] | B12: Test registration with valid input : - Email - Password - Repassword - Full name | C12: 1. Enter "http://localhost:5173/" to navigate to the website. (Top-right corner of the screen) 2. Guest user click the “Đăng ký” button. 3. The site displays the registration form. 4. Guest user select a registration role: “Student” or “Lecturer.” 5. Enter the following valid information: - Email: student@gmail.com - Password: Student@123 - RePassword: Student@123 - Full Name: Nguyen Van A 6. Guest user click the “Đăng ký” button. 7. Guest user ou are redirected to the “Đăng nhập” screen. | D12: - The guest user successfully registered, is redirected to the login page and the user details are stored in the database. - Notification display system "Đăng ký thành công! Vui lòng kiểm tra email để xác thực tài khoản." - The system sends authentication to the registered user's email. | E12: Server must be work Guest user is not logged in and wants to create an account. | F12: Passed | G12: 45998 | H12: TuanCM | I12: Passed | J12: 46001 | K12: TuanCM | L12: Passed | M12: 46003 | N12: TuanCM
A13: [Authen - 2] | B13: Test registration with valid input : - Email - Password - Repassword - Full name | C13: 1. Enter "http://localhost:5173/" to navigate to the website. (Top-right corner of the screen) 2. Guest user clicks the “Đăng ký” button. 3. The site displays the registration form. 4. Guest user selects a registration role: “Student” or “Lecturer.” 5.Guest user enter invalid email form(e.g., quatbt.com) 6. Guest user clicks the “Đăng ký” button. 7. Website displays an error message for invaild email format 8. Guest user corrects the mail format and resubmits the form. | D13: System displays an error message for the empty fields and prevents registration until corrected. | E13: Server must be work Guest user is not logged in and wants to create an account. | F13: Passed | G13: 45998 | H13: TuanCM | I13: Passed | J13: 46001 | K13: TuanCM | L13: Passed | M13: 46003 | N13: TuanCM
A14: [Authen - 3] | B14: Test registration with valid input : - Email - Password - Repassword - Full name | C14: 1. Enter "http://localhost:5173/" to navigate to the website. (Top-right corner of the screen) 2. Guest user click the “Đăng ký” button. 3. The site displays the registration form. 4. Guest user select a registration role: “Student” or “Lecturer.” 5. Enter the following valid information: - Email: empty - Password: empty - RePassword: empty - Full Name: empty 6. The registration form displays the message "vui lòng điền vào trường này". 7. The guest user corrects the inputs so no field is left blank and the format is valid, then submits the form. | D14: System displays an error message for the empty fields and prevents registration until corrected. | E14: Server must be work Guest user is not logged in and wants to create an account. | F14: Passed | G14: 45998 | H14: TuanCM | I14: Passed | J14: 46001 | K14: TuanCM | L14: Passed | M14: 46003 | N14: TuanCM
A15: [Authen - 4] | B15: Test registration with password must be shorter than 6 characters | C15: 1. Enter "http://localhost:5173/" to navigate to the website. (Top-right corner of the screen) 2. Guest user click the “Đăng ký” button. 3. The site displays the registration form. 4. Guest user select a registration role: “Student” or “Lecturer.” 5. Guest user enters a Password shorter than 6 characters (e.g., pass2). 6. Website displays an error message indicating "Mật khẩu phải có ít nhất 6 ký tự" 7. Guest user corrects the Password and resubmits the form. | D15: Displays an error message indicating "Mật khẩu phải có ít nhất 6 ký tự" | E15: Server must be work Guest user is not logged in and wants to create an account. | F15: Passed | G15: 45998 | H15: TuanCM | I15: Passed | J15: 46001 | K15: TuanCM | L15: Passed | M15: 46003 | N15: TuanCM
A16: [Authen - 5] | B16: Test registration with valid input : - Email - Password - Repassword - Full name | C16: 1. Enter "http://localhost:5173/" to navigate to the website. (Top-right corner of the screen) 2. Guest user clicks the “Đăng ký” button. 3. The site displays the registration form. 4. Guest user selects a registration role: “Student” or “Lecturer.” 5.The guest user enters a confirmation password that does not match the password (e.g., Password: Student@123, Confirm Password: studenta12). 6. Guest user clicks the “Đăng ký” button. 7. The website displays the message "Mật khẩu không khớp". 8. The guest user corrects the confirm password and resubmits the form. | D16: Displays an error message indicating "Mật khẩu không khớp" | E16: Server must be work Guest user is not logged in and wants to create an account. | F16: Passed | G16: 45998 | H16: TuanCM | I16: Passed | J16: 46001 | K16: TuanCM | L16: Passed | M16: 46003 | N16: TuanCM
A17: [Authen - 6] | B17: Test registration with valid input : - Email - Password - Repassword - Full name | C17: 1. Enter "http://localhost:5173/" to navigate to the website. (Top-right corner of the screen) 2. Guest user clicks the “Đăng ký” button. 3. The site displays the registration form. 4. Guest user selects a registration role: “Student” or “Lecturer.” 5.Guest user enters an email address that already exists in the system. 6. Guest user clicks the “Đăng ký” button. 7. The website displays the message "Email đã tồn tại hoặc có lỗi xảy ra". 8. The guest user corrects the email and resubmits the form. | D17: Displays an error message indicating "Email đã tồn tại hoặc có lỗi xảy ra" | E17: Server must be work Guest user is not logged in and wants to create an account. | F17: Passed | G17: 45998 | H17: TuanCM | I17: Passed | J17: 46001 | K17: TuanCM | L17: Passed | M17: 46003 | N17: TuanCM
A18: Login by account
A19: [Authen - 7] | B19: Check if the user can successfully log in with a valid email and password. | C19: 1. Enter "http://localhost:5173/" to go to website 2. Location in the right corner of the screen: - Click on "Đăng nhập" button 3. Fill in information including: - Email: user@example.com - Password: String 4. Click "Đăng nhập" button | D19: System displays message "Đăng nhập thành công!" | E19: Server must be work Guest user is not logged in and wants to create an account. | F19: Passed | G19: 45998 | H19: TuanCM | I19: Passed | J19: 46001 | K19: TuanCM | L19: Passed | M19: 46003 | N19: TuanCM
A20: [Authen - 8] | B20: Check if the website handles an incorrect password. | C20: 1. Enter "http://localhost:5173/" to go to website 2. Location in the right corner of the screen: - Click on "Đăng nhập" button 3. Fill in information including: - Email: user@example.com - Password: String1111 4. Click "Đăng nhập" button | D20: System displays message "Email hoặc mật khẩu không đúng" | E20: Server must be work Guest user is not logged in and wants to create an account. | F20: Passed | G20: 45998 | H20: TuanCM | I20: Passed | J20: 46001 | K20: TuanCM | L20: Passed | M20: 46003 | N20: TuanCM
A21: [Authen - 9] | B21: Check if the website handles an unregistered email address. | C21: 1. Enter "http://localhost:5173/" to go to website 2. Location in the right corner of the screen: - Click on "Đăng nhập" button 3. Fill in information including: - Email: user11@example.com - Password: String 4. Click "Đăng nhập" button | D21: System displays message "Email hoặc mật khẩu không đúng" | E21: Server must be work Guest user is not logged in and wants to create an account. | F21: Passed | G21: 45998 | H21: TuanCM | I21: Passed | J21: 46001 | K21: TuanCM | L21: Passed | M21: 46003 | N21: TuanCM
A22: Login by google
A23: [Authen - 10] | B23: Check if the user can successfully log in using a valid Google account. | C23: 1. Enter "http://localhost:5173/" to navigate to the website. (Top-right corner of the screen) 2. Guest user click the “Đăng nhập” button. 3. Click on the "Tiếp tục sử dụng dịch vụ bằng google" button. 4. The system redirects to Google’s login page. 5. The system redirects back to the application, showing the user's dashboard or homepage". | D23: System displays message "Đăng nhập Google thành công" | E23: 1.Server must be work 2..Account must be in system | F23: Passed | G23: 45998 | H23: TuanCM | I23: Passed | J23: 46001 | K23: TuanCM | L23: Passed | M23: 46003 | N23: TuanCM
A24: Forgot password
A25: [Authen - 11] | B25: Verify if the user can request a password reset by entering a valid registered email address. | C25: 1. Enter "http://localhost:5173/" to navigate to the website. (Top-right corner of the screen) 2. Guest user click the “Đăng nhập” button. 3. Guest user clicks on link "Quên mật khẩu?". 4. The system displays a form asking the user to enter their registered email address. 5. The user enters their email address and clicks the "Gửi email khôi phục" button. 6. The system sends a password reset email with a reset link to the user’s registered email address. 7. Redirect to "Đặt lại mật khẩu" screen 6. User enter the following valid information: - Mật khẩu mới: Student@123 - Xác nhận mật khẩu mới: Student@123 7. Click on "Đặt lại mật khẩu" button | D25: System displays message "Đặt lại mật khẩu thành công" | E25: 1.Server must be work 2..Account must be in system | F25: Passed | G25: 45998 | H25: TuanCM | I25: Passed | J25: 46001 | K25: TuanCM | L25: Passed | M25: 46003 | N25: TuanCM
A26: [Authen - 12] | B26: Enter non-existent email | C26: 1. Enter "http://localhost:5173/" to navigate to the website. (Top-right corner of the screen) 2. Guest user click the “Đăng nhập” button. 3. Guest user clicks on link "Quên mật khẩu?". 4. The system displays a form asking the user to enter their registered email address. 5. User enters an email that is not registered in the system (e.g., nanhnanh07@gmail.com). 6. Clicks the "Gửi email khôi phục" button. | D26: System displays message "Email không tồn tại hoặc chưa xác thực" | E26: 1.Server must be work 2..Account must be in system | F26: Passed | G26: 45998 | H26: TuanCM | I26: Passed | J26: 46001 | K26: TuanCM | L26: Passed | M26: 46003 | N26: TuanCM
A27: Logout
A28: [Authen - 13] | B28: Check if the user can successfully log out from the website. | C28: 1. Enter "http://localhost:5173/" to go to website 2. Guest user login with system. 3.Click the avatar icon in top-right of website. 4. Click "Đăng xuất" button. | D28: - User is logged out and redirect home page. No user-specific data is accessible until the user logs in again. - Show message "Đăng xuất thành công!" | E28: 1.Server must be work 2..Account must be in system | F28: Passed | G28: 45998 | H28: TuanCM | I28: Passed | J28: 46001 | K28: TuanCM | L28: Passed | M28: 46003 | N28: TuanCM
A29: [Authen - 14] | B29: Check if a logged-out user is restricted from accessing pages meant for logged-in users. | C29: 1. Enter "http://localhost:5173/" to go to website 2. Guest user login with system. 3.Click the avatar icon in top-right of website. 4. Click "Đăng xuất" button. 5. After logging out, try to directly access the restricted page by entering the URL in the browser. | D29: The system redirects the user to the homepage when they try to access the restricted page. | E29: 1.Server must be work 2..Account must be in system | F29: Failed | G29: 45998 | H29: TuanCM | I29: Passed | J29: 46001 | K29: TuanCM | L29: Passed | M29: 46003 | N29: TuanCM | O29: Round 1, 07/12/2025: The system did not redirect the user to the homepage when they try to accesses the restricted page.
A30: [Authen - 15] | B30: Register to become a lecturer | C30: 1. Enter "http://localhost:5173/" to navigate to the website. (Top-right corner of the screen) 2. Guest user click the “Đăng ký” button. 3. The site displays the registration form. 4. Guest user select a registration role: “Student” or “Lecturer.” 5. Enter the following valid information: - Email: lecturer@gmail.com - Password: Lecturer@123 - RePassword: Lecturer@123 - Full Name: Nguyen Van A 6. Guest user click the “Đăng ký” button. 7. Guest user ou are redirected to the “Đăng nhập” screen. 8. The guest user logs into the system using the newly registered account. 9. The system redirects to the Lecturer Application submission page. 10. Enter the following valid information: - Chức danh: Senior - Chuyên môn: Web Developer - Mô tả kinh nghiệm: 5 years as a software engineer - Tải lên CV: PDF file - Tải lên ảnh bằng cấp: Image file (e.g., .png, .jpg...). 11. The user clicks the “Nộp đơn ứng tuyển” button. | D30: System displays message "Nộp CV thành công! Chúng tôi sẽ liên hệ với bạn sớm." | E30: 1.Server must be work 2..Account must be in system | F30: Passed | G30: 45998 | H30: TuanCM | I30: Passed | J30: 46001 | K30: TuanCM | L30: Passed | M30: 46003 | N30: TuanCM

Sheet Workflow of Student
A2: Workflow | B2: Workflow of Student | R2: Passed
A3: Test requirement | B3: Perform the functionalities of role Student | R3: Failed
A4: Number of TCs | B4: 33 | R4: Pending
A5: Testing Round | B5: Passed | C5: Failed | D5: Pending | E5: N/A | R5: N/A
A6: Round 1 | B6: =COUNTIF($F10:$F1025,B5) -> 33 | C6: =COUNTIF($F10:$F1025,C5) -> 0 | D6: =COUNTIF($F10:$F1025,D5) -> 0 | E6: =COUNTIF($F10:$F1025,E5) -> 0
A7: Round 2 | B7: =COUNTIF($F10:$F1025,B5) -> 33 | C7: =COUNTIF($F10:$F1025,C5) -> 0 | D7: =COUNTIF($F10:$F1025,D5) -> 0 | E7: =COUNTIF($F10:$F1025,E5) -> 0
A8: Round 3 | B8: =COUNTIF($F10:$F1025,B5) -> 33 | C8: =COUNTIF($F10:$F1025,C5) -> 0 | D8: =COUNTIF($F10:$F1025,D5) -> 0 | E8: =COUNTIF($F10:$F1025,E5) -> 0
A10: Test Case ID | B10: Test Case Description | C10: Test Case Procedure | D10: Expected Results | E10: Pre-conditions | F10: Round 1 | G10: Test date | H10: Tester | I10: Round 2 | J10: Test date | K10: Tester | L10: Round 3 | M10: Test date | N10: Tester | O10: Note
A11: Ticket Features
A12: [Ticket - 1] | B12: View ticket list for Students/Lecturer | C12: 1. Login the system with the Student/Lecturer Role. 2. Click the "Phiếu hỗ trợ" tab in the header menu. | D12: The ticket list is displayed correctly with the following informations: - Ticket filter - Create new Ticket button - The list of that user's submitted tickets along with view Details button for each | E12: - The server must be working - User role must be Student or Lecturer - The account status must be "Active" | F12: Passed | G12: 45998 | H12: TuanCM | I12: Passed | J12: 46001 | K12: TuanCM | L12: Passed | M12: 46003 | N12: TuanCM
A13: [Ticket - 2] | B13: Verify filter functionality of the View ticket list for Student/Lecturer screen | C13: 1. Login the system with the Student/Lecturer Role. 2. Click the "Phiếu hỗ trợ" tab in the header menu. 3. Click the "Phiếu đã duyệt", "Phiếu bị từ chối" or "Tất cả phiếu" in the filter menu on the left. | D13: The ticket list is displayed correctly corresponding to the selected filter with the following informations: - Ticket filter - Create new Ticket button - The list of that user's submitted tickets along with view Details button for each | E13: - The server must be working - User role must be Student or Lecturer - The account status must be "Active" | F13: Passed | G13: 45998 | H13: TuanCM | I13: Passed | J13: 46001 | K13: TuanCM | L13: Passed | M13: 46003 | N13: TuanCM
A14: [Ticket - 3] | B14: Verify the Create new Ticket feature | C14: 1. Login the system with the Student/Lecturer Role. 2. Click the "Phiếu hỗ trợ" tab in the header menu. 3. Click the "Tạo phiếu mới" button on the left. 4. Input the "Tiêu đề" and "Nội dung" field for Title and Content in the popup window. 5. Click the "Tạo phiếu" button. | D14: - Successfully create a new Ticket in the system, which can be found in the User's ticket list and System Moderator Ticket List. - The newly created Ticket display the inputted informations correctly. | E14: - The server must be working - User role must be Student or Lecturer - The account status must be "Active" | F14: Passed | G14: 45998 | H14: TuanCM | I14: Passed | J14: 46001 | K14: TuanCM | L14: Passed | M14: 46003 | N14: TuanCM
A15: [Ticket - 4] | B15: Test the Create new Ticket with empty Title. | C15: 1. Login the system with the Student/Lecturer Role. 2. Click the "Phiếu hỗ trợ" tab in the header menu. 3. Click the "Tạo phiếu mới" button on the left. 4. Leave the "Tiêu đề" input fields blank. 5. Click the "Tạo phiếu" button. | D15: - The system send out error message below the blank inputted field. - No new Ticket is created. | E15: - The server must be working - User role must be Student or Lecturer - The account status must be "Active" | F15: Passed | G15: 45998 | H15: TuanCM | I15: Passed | J15: 46001 | K15: TuanCM | L15: Passed | M15: 46003 | N15: TuanCM
A16: [Ticket - 5] | B16: Test the Create new Ticket with empty Content. | C16: 1. Login the system with the Student/Lecturer Role. 2. Click the "Phiếu hỗ trợ" tab in the header menu. 3. Click the "Tạo phiếu mới" button on the left. 4. Leave the "Nội dung" input fields blank. 5. Click the "Tạo phiếu" button. | D16: - The system send out error message below the blank inputted field. - No new Ticket is created. | E16: - The server must be working - User role must be Student or Lecturer - The account status must be "Active" | F16: Passed | G16: 45998 | H16: TuanCM | I16: Passed | J16: 46001 | K16: TuanCM | L16: Passed | M16: 46003 | N16: TuanCM
A17: [Ticket - 6] | B17: Verify the View Ticket Details feature. | C17: 1. Login the system with the Student/Lecturer Role. 2. Click the "Phiếu hỗ trợ" tab in the header menu. 3. Click the "Xem" button on the right of a ticket. | D17: The ticket details page is displayed correctly with the following informations: - User's name - Submitted date and time - Response of the System Moderator - Ticket's Code - Ticket's Status | E17: - The server must be working - User role must be Student or Lecturer - The account status must be "Active" | F17: Passed | G17: 45998 | H17: TuanCM | I17: Passed | J17: 46001 | K17: TuanCM | L17: Passed | M17: 46003 | N17: TuanCM
A18: [Ticket - 7] | B18: Verify the View Ticket Details feature. | C18: 1. Login the system with the Student/Lecturer Role. 2. Click the "Phiếu hỗ trợ" tab in the header menu. 3. Click the "Xem" button on the right of a ticket. | D18: The ticket details page is displayed correctly with the following informations: - User's name - Submitted date and time - Response of the System Moderator - Ticket's Code - Ticket's Status | E18: - The server must be working - User role must be Student or Lecturer - The account status must be "Active" | F18: Passed | G18: 45998 | H18: TuanCM | I18: Passed | J18: 46001 | K18: TuanCM | L18: Passed | M18: 46003 | N18: TuanCM
A19: [Ticket - 8] | B19: Verify the Update Ticket feature. | C19: 1. Login the system with the Student/Lecturer Role. 2. Click the "Phiếu hỗ trợ" tab in the header menu. 3. Click the "Xem" button on the right of a ticket. 4. Click the "Cập nhật phiếu" button on the right. 5. Edit the fields informations of the Ticket. 6. Click the "Lưu thay đổi" button | D19: - Successfully update the Ticket in the system. - The updated Ticket display the inputted informations correctly. | E19: - The server must be working - User role must be Student or Lecturer - The account status must be "Active" - The Ticket status must be "Pending" | F19: Passed | G19: 45998 | H19: TuanCM | I19: Passed | J19: 46001 | K19: TuanCM | L19: Passed | M19: 46003 | N19: TuanCM
A20: [Ticket - 9] | B20: Test the Update Ticket with empty Title. | C20: 1. Login the system with the Student/Lecturer Role. 2. Click the "Phiếu hỗ trợ" tab in the header menu. 3. Click the "Xem" button on the right of a ticket. 4. Click the "Cập nhật phiếu" button on the right. 5. Leave the "Tiêu đề" field blank . 6. Click the "Lưu thay đổi" button | D20: - The system send out error message below the blank inputted field. - No update is made. | E20: - The server must be working - User role must be Student or Lecturer - The account status must be "Active" - The Ticket status must be "Pending" | F20: Passed | G20: 45998 | H20: TuanCM | I20: Passed | J20: 46001 | K20: TuanCM | L20: Passed | M20: 46003 | N20: TuanCM
A21: [Ticket - 10] | B21: Test the Update Ticket with empty Content. | C21: 1. Login the system with the Student/Lecturer Role. 2. Click the "Phiếu hỗ trợ" tab in the header menu. 3. Click the "Xem" button on the right of a ticket. 4. Click the "Cập nhật phiếu" button on the right. 5. Leave the "Nội dung" field blank . 6. Click the "Lưu thay đổi" button | D21: - The system send out error message below the blank inputted field. - No update is made. | E21: - The server must be working - User role must be Student or Lecturer - The account status must be "Active" - The Ticket status must be "Pending" | F21: Passed | G21: 45998 | H21: TuanCM | I21: Passed | J21: 46001 | K21: TuanCM | L21: Passed | M21: 46003 | N21: TuanCM
A22: Buying Course
A23: [Buy - 1] | B23: Verify student can add a free course to cart | C23: 1. Login as Student 2. Navigate to Course Detail page for a free course 3. Click "Add to Cart" button 4. Verify cart count increases | D23: - Toast message: "Thêm vào giỏ hàng thành công" - Cart count badge updates (+1) - Course appears in cart | E23: - Student is logged in - Free course exists (price = 0) - Student not already enrolled | F23: Passed | G23: 45998 | H23: TuanCM | I23: Passed | J23: 46001 | K23: TuanCM | L23: Passed | M23: 46003 | N23: TuanCM
A24: [Buy - 2] | B24: Verify student can add a paid course to cart | C24: 1. Login as Student 2. Navigate to Course Detail page for paid course 3. Verify price is displayed correctly 4. Click "Add to Cart" button (Shopping Cart icon) 5. Check cart page | D24: - Success toast notification appears - Cart icon shows updated count - Course appears in cart with correct price | E24: - Student is logged in - Paid course exists (price > 0) - Course status = "Approved" | F24: Passed | G24: 45998 | H24: TuanCM | I24: Passed | J24: 46001 | K24: TuanCM | L24: Passed | M24: 46003 | N24: TuanCM
A25: [Buy - 3] | B25: Verify instant enrollment for free courses | C25: 1. Login as Student 2. Navigate to free course detail page 3. Click "Đăng ký miễn phí" button 4. Verify enrollment status | D25: -Success message: Course enrolled successfully - Course appears in "My Courses" page | E25: - Student logged in - Course price = 0 - Course is published and approved | F25: Passed | G25: 45998 | H25: TuanCM | I25: Passed | J25: 46001 | K25: TuanCM | L25: Passed | M25: 46003 | N25: TuanCM
A26: [Buy - 4] | B26: Verify payment flow for single course purchase | C26: 1. Login as Student 2. Navigate to paid course detail 3. Click "Mua ngay" button 4. Wait for PayOS redirect 5. Complete payment on PayOS gateway 6. Return to platform | D26: - PayOS payment page opens - After successful payment: redirect to success page - Course enrolled automatically - Transaction recorded in payment history | E26: - Valid PayOS configuration - Student has sufficient balance - Course price > 0 | F26: Passed | G26: 45998 | H26: TuanCM | I26: Passed | J26: 46001 | K26: TuanCM | L26: Passed | M26: 46003 | N26: TuanCM
A27: [Buy - 5] | B27: Verify voucher application reduces course price | C27: 1. Add course to cart 2. Navigate to cart 3. Enter valid voucher code for the course 4. Click "Apply" 5. Verify discount calculation | D27: - Discount amount displayed - Final price = Original price - Discount - Voucher badge shows on course item | E27: - Valid voucher exists for the course - Voucher not expired - Student meets voucher conditions | F27: Passed | G27: 45998 | H27: TuanCM | I27: Passed | J27: 46001 | K27: TuanCM | L27: Passed | M27: 46003 | N27: TuanCM
A28: [Buy - 6] | B28: Verify removing course from cart | C28: 1. Navigate to cart with items 2. Click remove/delete button on a course 3. Confirm removal 4. Check cart count | D28: - Course removed from cart list - Cart count decreases - Total amount recalculates | E28: - At least one course in cart | F28: Passed | G28: 45998 | H28: TuanCM | I28: Passed | J28: 46001 | K28: TuanCM | L28: Passed | M28: 46003 | N28: TuanCM
A29: [Buy - 7] | B29: Verify bulk purchase from cart | C29: 1. Add 2+ courses to cart 2. Apply vouchers (optional) 3. Click "Thanh toán" button 4. Complete PayOS payment 5. Verify enrollments | D29: - All courses enrolled after payment - Cart cleared after successful payment - All courses appear in "My Courses" - Single transaction created for bundle | E29: - Multiple courses in cart - Valid payment method | F29: Passed | G29: 45998 | H29: TuanCM | I29: Passed | J29: 46001 | K29: TuanCM | L29: Passed | M29: 46003 | N29: TuanCM
A30: [Buy - 8] | B30: Verify guest users can add courses to cart | C30: 1. Log out (guest mode) 2. Browse course catalog 3. Click "Add to Cart" on course 4. Check localStorage for cart data | D30: - Toast: "Vui lòng đăng nhập để mua khóa học" - Course stored in localStorage - Cart count shows from localStorage | E30: - Not logged in - Browser allows localStorage | F30: Passed | G30: 45998 | H30: TuanCM | I30: Passed | J30: 46001 | K30: TuanCM | L30: Passed | M30: 46003 | N30: TuanCM
A31: [Buy - 9] | B31: Verify system prevents buying already enrolled course | C31: 1. Login as Student 2. Navigate to already enrolled course 3. Check button state on course detail | D31: - "Học ngay" button displayed instead of "Mua ngay" - Add to cart button disabled - Clicking redirects to learning page | E31: - Student already enrolled in course | F31: Passed | G31: 45998 | H31: TuanCM | I31: Passed | J31: 46001 | K31: TuanCM | L31: Passed | M31: 46003 | N31: TuanCM
A32: [Buy - 10] | B32: Verify enrollment after successful payment | C32: 1. Complete payment flow (TC_BUY_004) 2. Navigate to /student/my-courses 3. Check enrollment API response | D32: - Course appears in enrolled courses list - Progress bar shows 0% initially | E32: - Payment completed successfully - Payment webhook processed | F32: Passed | G32: 45998 | H32: TuanCM | I32: Passed | J32: 46001 | K32: TuanCM | L32: Passed | M32: 46003 | N32: TuanCM
A33: Learning Course
A34: [Learning - 1] | B34: Verify student can access course learning page | C34: 1. Login as Student 2. Navigate to "My Courses" 3. Click on enrolled course 4. Verify redirect to /student/learn/{courseId} | D34: - Course overview page loads - Shows all sections and lessons - Progress indicators visible - No unauthorized access error | E34: - Student enrolled in course - Course has published content | F34: Passed | G34: 45998 | H34: TuanCM | I34: Passed | J34: 46001 | K34: TuanCM | L34: Passed | M34: 46003 | N34: TuanCM
A35: [Learning - 2] | B35: Verify course structure display | C35: 1. Access enrolled course learning page 2. Expand all sections 3. Count lessons, videos, quizzes | D35: - All sections listed - Each section shows: title, description, item count - Icons differentiate: Video, Text, Quiz - Completed items marked with checkmark | E35: - Course has ≥1 section - Section has ≥1 item | F35: Passed | G35: 45998 | H35: TuanCM | I35: Passed | J35: 46001 | K35: TuanCM | L35: Passed | M35: 46003 | N35: TuanCM
A36: [Learning - 3] | B36: Verify video lesson playback | C36: 1. Navigate to course learning 2. Click on video lesson 3. Wait for video player to load 4. Play video 5. Verify tracking | D36: - Video player loads (React Player component) - Video plays without errors - Video controls available (play, pause, fullscreen) | E36: - Lesson type = "Video" - Valid video URL - Student enrolled | F36: Passed | G36: 45998 | H36: TuanCM | I36: Passed | J36: 46001 | K36: TuanCM | L36: Passed | M36: 46003 | N36: TuanCM
A37: [Learning - 4] | B37: Verify text content lesson display | C37: 1. Access text-based lesson 2. Scroll through content 3. Verify formatting | D37: - Content renders correctly - PDF viewer displays (if PDF type) - Text is readable and formatted - Lesson marked as viewed | E37: - Lesson type = "Text" or "PDF" - Content exists | F37: Passed | G37: 45998 | H37: TuanCM | I37: Passed | J37: 46001 | K37: TuanCM | L37: Passed | M37: 46003 | N37: TuanCM
A38: [Learning - 5] | B38: Verify lesson completion functionality | C38: 1. Access any lesson 2. Complete watching/reading 3. Click "Mark as Complete" button 4. Check progress update | D38: - Lesson marked with checkmark - Section progress percentage increases - Overall course progress updates | E38: - Student in lesson view - Lesson not already completed | F38: Passed | G38: 45998 | H38: TuanCM | I38: Passed | J38: 46001 | K38: TuanCM | L38: Passed | M38: 46003 | N38: TuanCM
A39: [Learning - 6] | B39: Verify lesson navigation | C39: 1. Access any lesson in middle of section 2. Click "Next" button 3. Verify navigation to next lesson 4. Click "Previous" button 5. Verify navigation to previous lesson | D39: - Smooth transition animation - Correct lesson loads - CourseSidebar highlights current lesson | E39: - Section has ≥2 lessons | F39: Passed | G39: 45998 | H39: TuanCM | I39: Passed | J39: 46001 | K39: TuanCM | L39: Passed | M39: 46003 | N39: TuanCM
A40: [Learning - 7] | B40: Verify quiz taking functionality | C40: 1. Navigate to quiz item 2. Click "Start Quiz" 3. Answer all questions 4. Submit quiz 5. View results | D40: - Redirects to /student/quiz/{quizId}/take - Timer displays - Can select answers - Submit enabled only when all answered - Score calculated: must pass passPercent threshold | E40: - Quiz has ≥1 question - Student enrolled in course | F40: Passed | G40: 45998 | H40: TuanCM | I40: Passed | J40: 46001 | K40: TuanCM | L40: Passed | M40: 46003 | N40: TuanCM
A41: [Learning - 8] | B41: Verify progress calculation accuracy | C41: 1. Start new course (0% progress) 2. Complete 1 lesson 3. Check progress percentage 4. Complete entire section 5. Verify progress updates | D41: - Progress bar updates in real-time - CourseSidebar shows percentage | E41: - Course has countable items - Student enrolled | F41: Passed | G41: 45998 | H41: TuanCM | I41: Passed | J41: 46001 | K41: TuanCM | L41: Passed | M41: 46003 | N41: TuanCM
A42: [Learning - 9] | B42: Verify sidebar course navigation | C42: 1. Open learning page 2. Click different sections in sidebar 3. Jump to specific lesson 4. Verify responsive behavior (mobile) | D42: - Sidebar shows all sections - Current lesson highlighted - Clicking navigates correctly - Completed items show checkmark icon | E42: - Learning page loaded | F42: Passed | G42: 45998 | H42: TuanCM | I42: Passed | J42: 46001 | K42: TuanCM | L42: Passed | M42: 46003 | N42: TuanCM
...

Sheet Workflow of Lecturer
A2: Workflow | B2: Workflow of Lecturer | R2: Passed
A3: Test requirement | B3: Perform the functionalities of role Lecturer | R3: Failed
A4: Number of TCs | B4: 63 | R4: Pending
A5: Testing Round | B5: Passed | C5: Failed | D5: Pending | E5: N/A | R5: N/A
A6: Round 1 | B6: =COUNTIF($F10:$F1060,B5) -> 63 | C6: =COUNTIF($F10:$F1060,C5) -> 0 | D6: =COUNTIF($F10:$F1060,D5) -> 0 | E6: =COUNTIF($F10:$F1060,E5) -> 0
A7: Round 2 | B7: =COUNTIF($F10:$F1060,B5) -> 63 | C7: =COUNTIF($F10:$F1060,C5) -> 0 | D7: =COUNTIF($F10:$F1060,D5) -> 0 | E7: =COUNTIF($F10:$F1060,E5) -> 0
A8: Round 3 | B8: =COUNTIF($F10:$F1060,B5) -> 63 | C8: =COUNTIF($F10:$F1060,C5) -> 0 | D8: =COUNTIF($F10:$F1060,D5) -> 0 | E8: =COUNTIF($F10:$F1060,E5) -> 0
A10: Test Case ID | B10: Test Case Description | C10: Test Case Procedure | D10: Expected Results | E10: Pre-conditions | F10: Round 1 | G10: Test date | H10: Tester | I10: Round 2 | J10: Test date | K10: Tester | L10: Round 3 | M10: Test date | N10: Tester | O10: Note
A11: Create Course
A12: [Create Course - 1] | B12: Test navigation to course creation page from side menu | C12: 1. Login to the system with approved Lecturer credentials 2. Locate "Khóa học" menu item in the left side menu 3. Click on "Khóa học" 4. Verify course management page loads 5. Locate "Tạo khóa học mới" button in the top right corner 6. Verify button is visible and enabled | D12: - "Khóa học" menu item is visible in side menu - "Khóa học" menu item is clickable - Course management page loads within 3 seconds - Page displays existing courses (if any) or empty state - "Tạo khóa học mới" button is visible in top right - "Tạo khóa học mới" button is enabled and clickable - No console errors occur - Course creation form appears as modal or new page | E12: - User has valid Lecturer account - User has logged into the system successfully - User's application to be Lecturer has been approved | F12: Passed | G12: 45998 | H12: TuanCM | I12: Passed | J12: 46001 | K12: TuanCM | L12: Passed | M12: 46003 | N12: TuanCM
A13: [Create Course - 2] | B13: Test course creation form display | C13: 1. Complete steps from [Course - 1] 2. Click "Tạo khóa học mới" button 3. Observe the form that appears 4. Verify all form fields are present 5. Verify form layout matches design | D13: - Form displays clearly with proper layout - All required fields are marked with asterisk (*) or "Required" label - Form includes fields for: Course title (required) * Course description (required) * Course category (required) - Form has "Tạo khóa học" button - Form has "Hủy" button to close | E13: - [Create Course - 1] passed successfully - User is on course management page | F13: Passed | G13: 45998 | H13: TuanCM | I13: Passed | J13: 46001 | K13: TuanCM | L13: Passed | M13: 46003 | N13: TuanCM
A14: [Create Course - 3] | B14: Test creating course with all required field filled correctly | C14: 1. Open course creation form (complete [Course - 2 ]) 2. Enter course title: "Kiểm thử phần mềm nâng cao" 3. Enter course description: "Khóa học chuyên sâu về các kỹ thuật kiểm thử phần mềm hiện đại, bao gồm kiểm thử tự động, course list or course kiểm thử hiệu năng và kiểm thử bảo mật" 4. Select category: "Học IT" 5. Select subcategory: "C++" 6. Upload an image 7. Click "Tạo khóa học" button 8. Wait for processing | D14: - All form fields accept input without errors - No validation errors appear - Form submits successfully - Success toast notification appears with message like "Tạo khóa học thành công" - Newest course appears on the top of the list - Course status is displayed as "Nháp" - Course shows "pen icon" for editing - Course shows "eye icon" for preview | E14: - [Create Course - 2] passed successfully - User has valid test data prepared | F14: Passed | G14: 45998 | H14: TuanCM | I14: Passed | J14: 46001 | K14: TuanCM | L14: Passed | M14: 46003 | N14: TuanCM
A15: [Create Course - 4] | B15: Test creating course with minimum valid length for text fields | C15: 1. Open course creation form 2. Enter course title with minimum allowed characters (test boundary: 5 characters): "Testing" 3. Enter course description with minimum allowed characters (test boundary: 20 characters): "Software testing intro" 4. Select valid category, subcategory 5. Click "Tạo khóa học" button | D15: - Form accepts minimum valid length - No validation errors for minimum boundary - Course is created successfully with "Nháp" status - Success notification appears - All entered data is saved correctly | E15: - [Create Course - 2] passed successfully | F15: Passed | G15: 45998 | H15: TuanCM | I15: Passed | J15: 46001 | K15: TuanCM | L15: Passed | M15: 46003 | N15: TuanCM
A16: [Create Course - 5] | B16: Test creating course with maximum valid length for text fields | C16: 1. Open course creation form 2. Enter course title at maximum allowed length (test boundary: assume 200 characters) 3. Enter course description at maximum allowed length (test boundary: assume 5000 characters) 4. Select valid category, subcategory 5. Fill other required fields 6. Click "Tạo khóa học" button | D16: - Form accepts maximum valid length without truncation - No validation errors - Course is created successfully - All text is saved completely without data loss | E16: - [Create Course - 2] passed successfully | F16: Passed | G16: 45998 | H16: TuanCM | I16: Passed | J16: 46001 | K16: TuanCM | L16: Passed | M16: 46003 | N16: TuanCM
A17: [Create Course - 6] | B17: Test creating course with special characters in allowed fields | C17: 1. Open course creation form 2. Enter course title with special characters: "Lập trình C++ & Python: From Zero to Hero!" 3. Enter description with special characters including: periods, commas, semicolons, quotes, parentheses, Vietnamese characters with diacritics 4. Fill other required fields 5. Click "Tạo khóa học" button | D17: - Form accepts valid special characters Vietnamese characters (á, à, ả, ã, ạ, ă, ắ, etc.) are handled correctly - Common punctuation marks are accepted - Course is created successfully - Special characters are displayed correctly (no encoding issues) - No XSS vulnerabilities (special characters are properly escaped) | E17: - [Create Course - 2] passed successfully | F17: Passed | G17: 45998 | H17: TuanCM | I17: Passed | J17: 46001 | K17: TuanCM | L17: Passed | M17: 46003 | N17: TuanCM
A18: [Create Course - 7] | B18: Test creating course with empty required field - Course Title | C18: 1. Open course creation form 2. Leave course title field EMPTY 3. Fill all other required fields with valid data 4. Click "Tạo khóa học" button 5. Observe validation behavior | D18: - Form does NOT submit - Validation error message appears near course title field - Error message is clear: "Tiêu đề khóa học là bắt buộc" or similar - User remains on the form - No course is created in database - Other field values are retained (not cleared) - Form does NOT submit | E18: - [Create Course - 2] passed successfully | F18: Passed | G18: 45998 | H18: TuanCM | I18: Passed | J18: 46001 | K18: TuanCM | L18: Passed | M18: 46003 | N18: TuanCM
A19: [Create Course - 8] | B19: Test creating course with empty required field - Course Description | C19: 1. Open course creation form 2. Fill course title with valid data 3. Leave course description field EMPTY 4. Fill all other required fields 5. Click "Tạo khóa học" button | D19: - Form does NOT submit - Validation error appears: "Mô tả khóa học là bắt buộc" - Description field is highlighted with error styling - User remains on form - No course is created - All entered data in other fields is preserved submit | E19: - [Create Course - 2] passed successfully | F19: Passed | G19: 45998 | H19: TuanCM | I19: Passed | J19: 46001 | K19: TuanCM | L19: Passed | M19: 46003 | N19: TuanCM
A20: [Create Course - 9] | B20: Test creating course with empty required field - Category | C20: 1. Open course creation form 2. Fill course title with valid data 3. Leave category selection empty 4. Fill all other required fields 5. Click "Tạo khóa học" button | D20: - Form does NOT submit - Validation error appears: "Mô tả khóa học là bắt buộc" - Description field is highlighted with error styling - User remains on form - No course is created - All entered data in other fields is preserved submit | E20: - [Create Course - 2] passed successfully | F20: Passed | G20: 45998 | H20: TuanCM | I20: Passed | J20: 46001 | K20: TuanCM | L20: Passed | M20: 46003 | N20: TuanCM
A21: [Create Course - 10] | B21: Test creating course with ALL required fields empty | C21: 1. Open course creation form 2. Fill course title with valid data 3. Leave category selection empty 4. Fill all other required fields 5. Click "Tạo khóa học" button | D21: - Each empty required field shows individual error message - All required fields are highlighted with error styling - Error messages are clear and specific to each field - No course is created - User can see all errors without scrolling (or form scrolls to first error) | E21: - [Create Course - 2] passed successfully | F21: Passed | G21: 45998 | H21: TuanCM | I21: Passed | J21: 46001 | K21: TuanCM | L21: Passed | M21: 46003 | N21: TuanCM
A22: Update course content
A23: [Update course - 1] | B23: Test accessing course edit mode via pen icon | C23: 1. Navigate to course list 2. Locate a draft course (e.g., "Khóa học dùng AI") 3. Click the pen (edit) icon | D23: - System navigates to course editing interface - URL changes to course edit page - Course editing page loads successfully | E23: - At least one draft course exists | F23: Passed | G23: 45998 | H23: TuanCM | I23: Passed | J23: 46001 | K23: TuanCM | L23: Passed | M23: 46003 | N23: TuanCM
A24: [Update course - 2] | B24: Test course editing interface layout | C24: 1. Access course edit page 2. Observe page structure and components | D24: - Page displays course name "System test" at top - Subtitle shows "Chỉnh sửa chi tiết khóa học" - Progress indicator shows "Tiến độ hoàn thành: 33%" in top right - Progress bar displays yellow color at 33% - "Quay lại khóa học" back button in top left - Left sidebar shows "QUẢN LÝ NỘI DUNG KHÓA HỌC" heading - Right content area shows current section content | E24: - User is on course edit page | F24: Passed | G24: 45998 | H24: TuanCM | I24: Passed | J24: 46001 | K24: TuanCM | L24: Passed | M24: 46003 | N24: TuanCM
A25: [Update course - 3] | B25: Test sidebar navigation menu structure | C25: 1. Access course edit page 2. Examine left sidebar menu items | D25: - Menu displays 4 main items in order: 1. "Trang giới thiệu" - with checkmark icon (green) and "Đã hoàn thành" status 2. "Khung chương trình" - with number "2" icon (yellow highlight) 3. "Giá khóa học" - with number "3" icon 4. "Phiếu giảm giá" - with tag icon and "(Tùy chọn)" label - Current section is highlighted in yellow - Completed sections show green checkmark icon - Incomplete sections show gray numbered icons | E25: - User is on course edit page | F25: Passed | G25: 45998 | H25: TuanCM | I25: Passed | J25: 46001 | K25: TuanCM | L25: Passed | M25: 46003 | N25: TuanCM
A26: [Update course - 4] | B26: Test progress overview section | C26: 1. Access course edit page 2. Locate "Tổng quan tiến độ" section in sidebar | D26: - Section displays "Tổng quan tiến độ" heading - Shows completion status: "Đã hoàn thành: 1/3 bước" - Text is in orange/yellow color - Clearly indicates only 1 out of 3 steps completed | E26: - User is on course edit page with basic info completed | F26: Passed | G26: 45998 | H26: TuanCM | I26: Passed | J26: 46001 | K26: TuanCM | L26: Passed | M26: 46003 | N26: TuanCM
A27: [Update course - 5] | B27: Test course publication readiness section | C27: 1. Access course edit page 2. Locate "Đề xuất khóa học" section at bottom of sidebar | D27: - Section displays paper plane icon - Shows text: "Đề xuất khóa học" - Shows requirement: "Hoàn thành 67% để đề xuất" - Section is grayed out/disabled when incomplete5. Indicates course cannot be submitted yet | E27: - Course is not yet complete (less than 100% progress) | F27: Passed | G27: 45998 | H27: TuanCM | I27: Passed | J27: 46001 | K27: TuanCM | L27: Passed | M27: 46003 | N27: TuanCM
A28: [Update course - 6] | B28: Test back navigation button | C28: 1. Access course edit page 2. Click "Quay lại khóa học" button 3. Observe navigation behavior | D28: - Button is clickable with left arrow icon - System navigates back to course list page - No unsaved changes are lost (or warning appears if changes exist) - User returns to "Quản lý khóa học" page | E28: - User is on course edit page | F28: Passed | G28: 45998 | H28: TuanCM | I28: Passed | J28: 46001 | K28: TuanCM | L28: Passed | M28: 46003 | N28: TuanCM
A29: [Update course - 7] | B29: Test editing course name | C29: 1. Navigate to "Trang giới thiệu" 2. Click on "Tên khóa học" field 3. Modify text to: "System test - Updated" 4. Click on "Mô tả khóa học" field 5. Modify description text 6. Click category dropdown 7. Select different category 8. Click category dropdown 9. Select different subcategory 10. Click "Chọn ảnh" or change image button 11. Select new image file 12. Click "Lưu" button | D29: - All fiedls are updated - Toast success show up | E29: - User is on introduction page | F29: Passed | G29: 45998 | H29: TuanCM | I29: Passed | J29: 46001 | K29: TuanCM | L29: Passed | M29: 46003 | N29: TuanCM
A30: [Update course - 8] | B30: Test accessing course structure page | C30: 1. Access course edit page 2. Click "Khung chương trình" in sidebar | D30: - Course structure page displays - Heading shows "Nội dung khóa học" - Shows "0 chương" count - "Chương mới" button visible in top right - Menu item "Khung chương trình" is highlighted | E30: - User is on introduction page | F30: Passed | G30: 45998 | H30: TuanCM | I30: Passed | J30: 46001 | K30: TuanCM | L30: Passed | M30: 46003 | N30: TuanCM
A31: [Update course - 9] | B31: Test empty state for course sections | C31: 1. Access "Khung chương trình" page 2. Observe empty state when no sections exist | D31: - Empty state message displays: - Document icon shown - Text: "Chưa có chương nào" - Subtitle: "Bắt đầu tạo chương đầu tiên" - "Tạo chương" button displayed in dashed border area - Clear call-to-action to create first section | E31: - User is on introduction page | F31: Passed | G31: 45998 | H31: TuanCM | I31: Passed | J31: 46001 | K31: TuanCM | L31: Passed | M31: 46003 | N31: TuanCM
A32: [Update course - 10] | B32: Test opening create section dialog | C32: 1. Access "Khung chương trình" page 2. Click "+ Tạo chương" button | D32: - Create section dialog/form appears - Form contains: + "Tên bài học" input field + "Mô tả bài học" textarea + "Thêm bài học" button + "Hủy" button | E32: - User is on introduction page | F32: Passed | G32: 45998 | H32: TuanCM | I32: Passed | J32: 46001 | K32: TuanCM | L32: Passed | M32: 46003 | N32: TuanCM
A33: [Update course - 11] | B33: Test section creation validation - empty title | C33: 1. Open create section dialog 2. Leave "Tên chương" field empty 3. Enter optional description 4. Click "Lưu" button | D33: -Form does not submit - Validation error appears for "Tên chương" - Error message indicates title is required - Dialog remains open | E33: - User is on introduction page | F33: Passed | G33: 45998 | H33: TuanCM | I33: Passed | J33: 46001 | K33: TuanCM | L33: Passed | M33: 46003 | N33: TuanCM
A34: [Update course - 12] | B34: Test section creation - valid data | C34: 1. Open create section dialog 2. Enter "Tên chương": "Chương 1: Hello world" 3. Leave description empty (optional) 4. Click "Lưu" button | D34: - Form validates successfully - Dialog closes - Section is created and appears in course structure - Success toast notification appears - Empty state disappears | E34: - User is on introduction page | F34: Passed | G34: 45998 | H34: TuanCM | I34: Passed | J34: 46001 | K34: TuanCM | L34: Passed | M34: 46003 | N34: TuanCM
... A44: [Update course - 22] | B44: Test quiz form validation - empty fields | C44: 1. Open quiz creation form 2. Leave all fields empty 3. Click "Tạo quiz" | D44: - Form does not submit - Validation errors appear for required fields - Error messages are clear | E44: - Quiz form is open | F44: Passed | G44: 45998 | H44: TuanCM | I44: Passed | J44: 46001 | K44: TuanCM | L44: Passed | M44: 46003 | N44: TuanCM
A45: [Update course - 23] | B45: Test creating quiz successfully | C45: 1. Open quiz creation form 2. Fill all required fields with valid data 3. Click "Tạo quiz" | D45: - Form validates successfully - Quiz is created - Success notification appears - Quiz appears in section - Section shows updated item count | E45: - All fields filled correctly | F45: Passed | G45: 45998 | H45: TuanCM | I45: Passed | J45: 46001 | K45: TuanCM | L45: Passed | M45: 46003 | N45: TuanCM | O45: Question addition is separate workflow
A46: [Update course - 24] | B46: Test initial pricing status display | C46: 1. Access pricing page for course without price set 2. Observe "Giá hiện tại" section | D46: - Status section shows: + Green dollar sign icon + "Giá hiện tại" heading + "Khóa học chưa được định giá" message in green - Guidelines displayed: + "Khóa học trả phí nên có giá trị rõ ràng và nội dung chất lượng" + "Bạn có thể thay đổi giá sau khi xuất bán" | E46: - Course has no price set | F46: Passed | G46: 45998 | H46: TuanCM | I46: Passed | J46: 46001 | K46: TuanCM | L46: Passed | M46: 46003 | N46: TuanCM
A47: [Update course - 25] | B47: Test pricing type options display | C47: 1. Access pricing page 2. Locate "Loại giá" section | D47: - Section displays with red asterisk (required) - Two radio button options: + "Miễn phí" with subtitle "Không yêu cầu thanh toán" + "Trả phí" with subtitle "Yêu cầu thanh toán" - One option can be selected at a time | E47: - Pricing page displayed | F47: Passed | G47: 45998 | H47: TuanCM | I47: Passed | J47: 46001 | K47: TuanCM | L47: Passed | M47: 46003 | N47: TuanCM
A48: [Update course - 26] | B48: Test selecting "Miễn phí" option | C48: 1. Access pricing page 2. Click "Miễn phí" radio button 3. Observe form changes | D48: - "Miễn phí" option is selected - Price input field is disabled or hidden - Warning message appears: "Bạn chưa lưu giá khóa học. Nhấn nút bên dưới để lưu thay đổi." - "Lưu thay đổi" button remains enabled | E48: - Pricing page displayed | F48: Passed | G48: 45998 | H48: TuanCM | I48: Passed | J48: 46001 | K48: TuanCM | L48: Passed | M48: 46003 | N48: TuanCM
A49: [Update course - 27] | B49: Test selecting "Trả phí" option | C49: 1. Access pricing page 2. Click "Trả phí" radio button 3. Observe form changes | D49: - "Trả phí" option is selected - "Giá khóa học (VNĐ)" input field appears/enables - Placeholder text: "Nhập giá khóa học (ví dụ: 100000)" - Suggested price buttons appear: 99,000đ, 199,000đ, 299,000đ, 499,000đ, 999,000đ5. "Gợi ý mức giá phổ biến:" label shown | E49: - Pricing page displayed | F49: Passed | G49: 45998 | H49: TuanCM | I49: Passed | J49: 46001 | K49: TuanCM | L49: Passed | M49: 46003 | N49: TuanCM
A50: [Update course - 28] | B50: Test saving free pricing | C50: 1. Select "Miễn phí" option 2. Click "Lưu thay đổi" button | D50: - Form submits successfully - Success toast appears: "Cập nhật giá khóa học thành công!" or similar - "Giá hiện tại" section updates to show: + "Miễn phí" + "Học viên có thể đăng ký miễn phí" - Warning message disappears5. Progress may update | E50: - "Miễn phí" selected | F50: Passed | G50: 45998 | H50: TuanCM | I50: Passed | J50: 46001 | K50: TuanCM | L50: Passed | M50: 46003 | N50: TuanCM
A51: [Update course - 29] | B51: Test saving paid pricing with valid price | C51: 1. Select "Trả phí" option 2. Enter valid price: "100000" or use suggested price 3. Click "Lưu thay đổi" | D51: - Form submits successfully - Success toast appears: "Cập nhật giá khóa học thành công!" - "Giá hiện tại" section updates to show the set price - Warning message disappears - Price is saved and displayed - Progress indicator may update | E51: - Valid price entered | F51: Passed | G51: 45998 | H51: TuanCM | I51: Passed | J51: 46001 | K51: TuanCM | L51: Passed | M51: 46003 | N51: TuanCM
...

Sheet AI Assistant
A2: Workflow | B2: AI assistant | R2: Passed
A3: Test requirement | B3: Perform of AI assistant for student learning | R3: Failed
A4: Number of TCs | B4: 5 | R4: Pending
A5: Testing Round | B5: Passed | C5: Failed | D5: Pending | E5: N/A | R5: N/A
A6: Round 1 | B6: =COUNTIF($F10:$F867,B5) -> 5 | C6: =COUNTIF($F10:$F867,C5) -> 0 | D6: =COUNTIF($F10:$F867,D5) -> 0 | E6: =COUNTIF($F10:$F867,E5) -> 0
A7: Round 2 | B7: =COUNTIF($F10:$F867,B5) -> 5 | C7: =COUNTIF($F10:$F867,C5) -> 0 | D7: =COUNTIF($F10:$F867,D5) -> 0 | E7: =COUNTIF($F10:$F867,E5) -> 0
A8: Round 3 | B8: =COUNTIF($F10:$F867,B5) -> 5 | C8: =COUNTIF($F10:$F867,C5) -> 0 | D8: =COUNTIF($F10:$F867,D5) -> 0 | E8: =COUNTIF($F10:$F867,E5) -> 0
A10: Test Case ID | B10: Test Case Description | C10: Test Case Procedure | D10: Expected Results | E10: Pre-conditions | F10: Round 1 | G10: Test date | H10: Tester | I10: Round 2 | J10: Test date | K10: Tester | L10: Round 3 | M10: Test date | N10: Tester | O10: Note
A11: AI response
A12: [AI -1] | B12: Verify AI response to video content summary request | C12: 1. Open chat with AI assistant 2. Type: "Nội dung của video này là gì?" 3. Send message4. Observe response | D12: - AI provides comprehensive summary of video content- Response includes main topics: null, undefined in JavaScript - Mentions 4 cases when undefined appears - Mentions null vs undefined comparison - Mentions Symbol data type - Response in Vietnamese | E12: - Login as Student - Own a course that has AI assist | F12: Passed | G12: 45998 | H12: TuanCM | I12: Passed | J12: 46001 | K12: TuanCM | L12: Passed | M12: 46003 | N12: TuanCM
A13: [AI -1] | B13: Verify AI response to irrelevant/nonsense input | C13: 1. Open chat with AI assistant 2. Type: "123" 3. Send message 4. Observe response | D13: - AI recognizes irrelevant input - Polite message indicating question is not related to lesson content - Suggests asking different question about the subtitle content - Response format: "Chào bạn, câu hỏi '123' không phải là một câu hỏi liên quan..." | E13: - Login as Student - Own a course that has AI assist | F13: Passed | G13: 45998 | H13: TuanCM | I13: Passed | J13: 46001 | K13: TuanCM | L13: Passed | M13: 46003 | N13: TuanCM
A14: [AI -1] | B14: Verify AI response to explicit summary request | C14: 1. Type: "Bạn có thể tóm tắt nội dung của video trên?" 2. Send message 3. Observe response | D14: - AI provides detailed summary - Greeting: "Chào bạn, SkillUp đây" - Summary covers all main points systematically - Mentions undefined cases clearly - Mentions null vs undefined comparison - Includes Symbol characteristics | E14: - Login as Student - Own a course that has AI assist | F14: Passed | G14: 45998 | H14: TuanCM | I14: Passed | J14: 46001 | K14: TuanCM | L14: Passed | M14: 46003 | N14: TuanCM
A15: [AI -1] | B15: Verify AI response to request for specific examples | C15: 1. Type: "Bạn có thể cung cấp 1 ví dụ cụ thể không?" 2. Send message 3. Observe response | D15: - AI acknowledges the request politely - Explains that subtitle content describes cases but doesn't provide code examples - States lesson focuses on theory and definitions - Response starts with "Chào bạn, SkillUp rất vui được hỗ trợ bạn" - Honest about content limitations | E15: Previous conversation exists | F15: Passed | G15: 45998 | H15: TuanCM | I15: Passed | J15: 46001 | K15: TuanCM | L15: Passed | M15: 46003 | N15: TuanCM
A16: [AI -1] | B16: Verify multilingualism | C16: 1. Type: "Can you summary this video ?" 2. Send message 3. Observe response | D16: - AI provides comprehensive summary of video content- Response includes main topics: null, undefined in JavaScript - Mentions 4 cases when undefined appears - Mentions null vs undefined comparison - Mentions Symbol data type - Response in Vietnamese" | E16: - Login as Student - Own a course that has AI assist | F16: Passed | G16: 45998 | H16: TuanCM | I16: Passed | J16: 46001 | K16: TuanCM | L16: Passed | M16: 46003 | N16: TuanCM

Sheet Workflow of System Moderator
A2: Workflow | B2: Workflow of System Moderator | R2: Passed
A3: Test requirement | B3: Check if the functionalities of System Moderator role work well. | R3: Failed
A4: Number of TCs | B4: 15 | R4: Pending
